<?xml version="1.0"?>
<!-- =================================================================================== -->
<!-- |    This document was autogenerated by xacro from
/home/dangtran/Desktop/Cpp_ros_projects_Alabama/src/dual_ur5_husky_mujoco/husky_description/urdf/dual_arm_husky.urdf.xacro
| -->
<!-- |    EDITING THIS FILE BY HAND IS NOT RECOMMENDED                                 | -->
<!-- =================================================================================== -->
<!-- =================================================================================== -->
<!-- |    This document was autogenerated by xacro from dual_arm_husky.urdf.xacro      | -->
<!-- |    EDITING THIS FILE BY HAND IS NOT RECOMMENDED                                 | -->
<!-- =================================================================================== -->
<!-- =================================================================================== -->
<!-- |    This document was autogenerated by xacro from description.xacro              | -->
<!-- |    EDITING THIS FILE BY HAND IS NOT RECOMMENDED                                 | -->
<!-- =================================================================================== -->
<!--
Software License Agreement (BSD)

\file      description.urdf.xacro
\authors   Paul Bovbel <pbovbel@clearpathrobotics.com>, Devon Ash <dash@clearpathrobotics.com>
\copyright Copyright (c) 2015, Clearpath Robotics, Inc., All rights reserved.

Redistribution and use in source and binary forms, with or without modification, are permitted
provided that
the following conditions are met:
 * Redistributions of source code must retain the above copyright notice, this list of conditions
and the
   following disclaimer.
 * Redistributions in binary form must reproduce the above copyright notice, this list of conditions
and the
   following disclaimer in the documentation and/or other materials provided with the distribution.
 * Neither the name of Clearpath Robotics nor the names of its contributors may be used to endorse
or promote
   products derived from this software without specific prior written permission.

THIS SOFTWARE IS PROVIDED BY THE COPYRIGHT HOLDERS AND CONTRIBUTORS "AS IS" AND ANY EXPRESS OR
IMPLIED WAR-
RANTIES, INCLUDING, BUT NOT LIMITED TO, THE IMPLIED WARRANTIES OF MERCHANTABILITY AND FITNESS FOR A
PARTICULAR
PURPOSE ARE DISCLAIMED. IN NO EVENT SHALL THE COPYRIGHT HOLDER OR CONTRIBUTORS BE LIABLE FOR ANY
DIRECT, IN-
DIRECT, INCIDENTAL, SPECIAL, EXEMPLARY, OR CONSEQUENTIAL DAMAGES (INCLUDING, BUT NOT LIMITED TO,
PROCUREMENT
OF SUBSTITUTE GOODS OR SERVICES; LOSS OF USE, DATA, OR PROFITS; OR BUSINESS INTERRUPTION) HOWEVER
CAUSED AND
ON ANY THEORY OF LIABILITY, WHETHER IN CONTRACT, STRICT LIABILITY, OR TORT (INCLUDING NEGLIGENCE OR
OTHERWISE)
ARISING IN ANY WAY OUT OF THE USE OF THIS SOFTWARE, EVEN IF ADVISED OF THE POSSIBILITY OF SUCH
DAMAGE.
-->
<robot name="husky">
  <!-- Included URDF/XACRO Files -->
  <!-- Inertia parameters -->
  <!-- This mass might be incorrect -->
  <!-- Kinematic model -->
  <!-- Properties from urcontrol.conf -->
  <!--
    DH for UR5:
    a = [0.00000, -0.42500, -0.39225,  0.00000,  0.00000,  0.0000]
    d = [0.089159,  0.00000,  0.00000,  0.10915,  0.09465,  0.0823]
    alpha = [ 1.570796327, 0, 0, 1.570796327, -1.570796327, 0 ]
    q_home_offset = [0, -1.570796327, 0, -1.570796327, 0, 0]
    joint_direction = [-1, -1, 1, 1, 1, 1]
    mass = [3.7000, 8.3930, 2.2750, 1.2190, 1.2190, 0.1879]
    center_of_mass = [ [0, -0.02561, 0.00193], [0.2125, 0, 0.11336], [0.11993, 0.0, 0.0265], [0,
  -0.0018, 0.01634], [0, 0.0018,0.01634], [0, 0, -0.001159] ]
  -->
  <!-- Arbitrary offsets for shoulder/elbow joints -->
  <!-- measured from model -->
  <!-- measured from model -->
  <!-- link lengths used in model -->
  <!--property
  name="shoulder_height" value="0.089159" /-->
  <!--property
  name="shoulder_offset" value="0.13585" /-->
  <!-- shoulder_offset - elbow_offset + wrist_1_length = 0.10915 -->
  <!--property
  name="upper_arm_length" value="0.42500" /-->
  <!--property
  name="elbow_offset" value="0.1197" /-->
  <!-- CAD measured -->
  <!--property
  name="forearm_length" value="0.39225" /-->
  <!--property
  name="wrist_1_length" value="0.093" /-->
  <!-- CAD measured -->
  <!--property
  name="wrist_2_length" value="0.09465" /-->
  <!-- In CAD this distance is 0.930, but in the spec it is 0.09465 -->
  <!--property
  name="wrist_3_length" value="0.0823" /-->
  <!-- manually measured -->
  <!-- manually measured -->
  <!-- manually measured -->
  <!-- manually measured -->
  <!-- manually measured -->
  <!-- Base Size -->
  <!-- Wheel Mounting Positions -->
  <!-- Wheel Properties -->
  <!-- Base link is the center of the robot's bottom plate -->
  <material name="dark_grey">
    <color rgba="0.3 0.3 0.3 1.0" />
  </material>
  <material name="medium_grey">
    <color rgba="0.6 0.6 0.6 1.0" />
  </material>
  <material name="light_grey">
    <color rgba="0.6 0.6 0.6 1.0" />
  </material>
  <material name="yellow">
    <color rgba="0.8 0.8 0.0 1.0" />
  </material>
  <material name="black">
    <color rgba="0.1 0.1 0.1 1.0" />
  </material>
  <material name="white">
    <color rgba="1.0 1.0 1.0 1.0" />
  </material>
  <material name="red">
    <color rgba="1.0 0.0 0.0 1.0" />
  </material>
  
  <material name="DarkGrey">
    <color rgba="0.3 0.3 0.3 1.0"/>
  </material>

  <material name="blue">
    <color rgba="0.67 0.85 0. 1.0"/>
  </material>



  <!-- <link name="world">
  </link>
  <joint name="world_to_base_link" type="fixed">
    <origin rpy="0 0 0" xyz="0 0 1.0" />
    <parent link="world" />
    <child link="base_link" />

  </joint> -->


  <!-- ########################################
       ########### Husky Mobile ###############
       ########################################
   -->

  <link name="base_link">
    <visual>
      <origin rpy="0 0 0" xyz="0 0 0" />
      <geometry>
        <mesh filename="package://husky_description/meshes/base_link.dae"/>
      </geometry>
      <material name="black"/>     
    </visual>
    <collision>
      <origin rpy="0 0 0" xyz="0 0 0.061875" />
      <geometry>
        <box size="0.9874 0.5709 0.12375" />
      </geometry>
    </collision>
    <collision>
      <origin rpy="0 0 0" xyz="0 0 0.185625" />
      <geometry>
        <box size="0.78992 0.5709 0.12375" />
      </geometry>
    </collision>
    <inertial>
      <origin xyz="0 0 0" rpy="0 0 0"/>
      <mass value="5.0"/>  <!-- A guess for a medium-sized metal link -->
      <inertia ixx="0.02" ixy="0.0" ixz="0.0" iyy="0.02" iyz="0.0" izz="0.01"/> <!-- Estimated values for a cuboid -->
    </inertial>      
  </link>
  <!-- Base footprint is on the ground under the robot -->
  <link name="base_footprint">
    <inertial>
      <origin xyz="0 0 0" rpy="0 0 0"/>
      <mass value="0.00001"/> <!-- Small non-zero mass -->
      <inertia ixx="0.00000001" ixy="0.0" ixz="0.0" iyy="0.00000001" iyz="0.0" izz="0.00000001"/> <!-- Small non-zero inertia values -->
    </inertial> 
  </link> 
  
  
  
  <joint name="base_footprint_joint" type="fixed">
    <origin rpy="0 0 0" xyz="0 0 -0.14493" />
    <parent link="base_link" />
    <child link="base_footprint" />
  </joint>
  <!-- Interial link stores the robot's inertial information -->
  <!-- -old -->
  <link name="inertial_link">
    <inertial>
      <mass value="0.39054" />
      <origin xyz="-0.0648 -0.00059 0.07895" />
      <inertia ixx="0.001634275613800003" ixy="-0.0055452352110000006" ixz="-0.041083822026"
        iyy="0.05314689495400002" iyz="-0.0004366145530000001" izz="-0.004759585875" />
    </inertial>
  </link>

  <!-- +New -->
  <!--   <link name="inertial_link">
    <inertial>
      <mass value="46.034" />
      <origin xyz="-0.00065 -0.085 0.062" />
      <inertia ixx="0.6022" ixy="-0.02364" ixz="-0.1197" iyy="1.7386" iyz="-0.001544" izz="2.0296" />
    </inertial>
  </link> -->

  <!-- ?Test -->
  <!-- <link name="inertial_link">
    <inertial>
      <mass value="200.0" />
      <origin xyz="-0.0648 -0.00059 0.07895" />
      <inertia ixx="0.001634275613800003" ixy="-0.0055452352110000006" ixz="-0.041083822026"
        iyy="0.05314689495400002" iyz="-0.0004366145530000001" izz="-0.004759585875" />
    </inertial>
  </link> -->

  <joint name="inertial_joint" type="fixed">
    <origin rpy="0 0 0" xyz="0 0 0" />
    <parent link="base_link" />
    <child link="inertial_link" />
  </joint>
  <!-- IMU Link is the standard mounting position for the UM6 IMU.-->
  <!-- Can be modified with environment variables in /etc/ros/setup.bash -->
  <link name="imu_link">
    <inertial>
      <origin xyz="0 0 0" rpy="0 0 0"/>
      <mass value="0.00001"/> <!-- Small non-zero mass -->
      <inertia ixx="0.00000001" ixy="0.0" ixz="0.0" iyy="0.00000001" iyz="0.0" izz="0.00000001"/> <!-- Small non-zero inertia values -->
    </inertial>    
  </link>  
  <joint name="imu_joint" type="fixed">
    <!-- <origin xyz="$(optenv HUSKY_IMU_XYZ 0.19 0 0.149)" rpy="$(optenv HUSKY_IMU_RPY 0 -1.5708
    3.1416)" /> -->
    <origin rpy="-1.5708 0 0" xyz="0.19 0 0.149" />
    <parent link="base_link" />
    <child link="imu_link" />
  </joint>
  <gazebo reference="imu_link">
  </gazebo>
  <!-- Husky wheel macros -->
  <link name="front_left_wheel_link">
    <inertial>
      <mass value="2.637" />
      <origin xyz="0 0 0" />
      <inertia ixx="0.02467" ixy="0" ixz="0" iyy="0.02467" iyz="0" izz="0.04411" />
    </inertial>
    <visual>
      <origin rpy="0 0 0" xyz="0 0 0" />
      <geometry>
        <mesh filename="package://husky_description/meshes/wheel.dae" />
      </geometry>
      <material name="DarkGrey"/>
    </visual>
    <collision>
      <origin rpy="1.570795 0 0" xyz="0 0 0" />
      <geometry>
        <cylinder length="0.1143" radius="0.17775" />
      </geometry>
    </collision>
  </link>
  <gazebo reference="front_left_wheel_link">
    <mu1 value="1.0" />
    <mu2 value="1.0" />
    <kp value="10000000.0" />
    <kd value="1.0" />
    <fdir1 value="1 0 0" />
  </gazebo>
  <joint name="front_left_wheel" type="continuous">
    <parent link="base_link" />
    <child link="front_left_wheel_link" />
    <origin rpy="0 0 0" xyz="0.256 0.2854 0.03282" />
    <axis rpy="0 0 0" xyz="0 1 0" />
  </joint>
  <transmission name="front_left_wheel_trans" type="SimpleTransmission">
    <type>transmission_interface/SimpleTransmission</type>
    <actuator name="front_left_wheel_motor">
      <mechanicalReduction>1</mechanicalReduction>
    </actuator>
    <joint name="front_left_wheel">
      <hardwareInterface>VelocityJointInterface</hardwareInterface>
    </joint>
  </transmission>
  <link name="front_right_wheel_link">
    <inertial>
      <mass value="2.637" />
      <origin xyz="0 0 0" />
      <inertia ixx="0.02467" ixy="0" ixz="0" iyy="0.02467" iyz="0" izz="0.04411" />
    </inertial>
    <visual>
      <origin rpy="0 0 0" xyz="0 0 0" />
      <geometry>
        <mesh filename="package://husky_description/meshes/wheel.dae" />
      </geometry>
      <material name="DarkGrey"/>
    </visual>
    <collision>
      <origin rpy="1.570795 0 0" xyz="0 0 0" />
      <geometry>
        <cylinder length="0.1143" radius="0.17775" />
      </geometry>
    </collision>
  </link>
  <gazebo reference="front_right_wheel_link">
    <mu1 value="1.0" />
    <mu2 value="1.0" />
    <kp value="10000000.0" />
    <kd value="1.0" />
    <fdir1 value="1 0 0" />
  </gazebo>
  <joint name="front_right_wheel" type="continuous">
    <parent link="base_link" />
    <child link="front_right_wheel_link" />
    <origin rpy="0 0 0" xyz="0.256 -0.2854 0.03282" />
    <axis rpy="0 0 0" xyz="0 1 0" />
  </joint>
  <transmission name="front_right_wheel_trans" type="SimpleTransmission">
    <type>transmission_interface/SimpleTransmission</type>
    <actuator name="front_right_wheel_motor">
      <mechanicalReduction>1</mechanicalReduction>
    </actuator>
    <joint name="front_right_wheel">
      <hardwareInterface>VelocityJointInterface</hardwareInterface>
    </joint>
  </transmission>
  <link name="rear_left_wheel_link">
    <inertial>
      <mass value="2.637" />
      <origin xyz="0 0 0" />
      <inertia ixx="0.02467" ixy="0" ixz="0" iyy="0.02467" iyz="0" izz="0.04411" />
    </inertial>
    <visual>
      <origin rpy="0 0 0" xyz="0 0 0" />
      <geometry>
        <mesh filename="package://husky_description/meshes/wheel.dae" />
      </geometry>
      <material name="DarkGrey"/>
    </visual>
    <collision>
      <origin rpy="1.570795 0 0" xyz="0 0 0" />
      <geometry>
        <cylinder length="0.1143" radius="0.17775" />
      </geometry>
    </collision>
  </link>
  <gazebo reference="rear_left_wheel_link">
    <mu1 value="1.0" />
    <mu2 value="1.0" />
    <kp value="10000000.0" />
    <kd value="1.0" />
    <fdir1 value="1 0 0" />
  </gazebo>
  <joint name="rear_left_wheel" type="continuous">
    <parent link="base_link" />
    <child link="rear_left_wheel_link" />
    <origin rpy="0 0 0" xyz="-0.256 0.2854 0.03282" />
    <axis rpy="0 0 0" xyz="0 1 0" />
  </joint>
  <transmission name="rear_left_wheel_trans" type="SimpleTransmission">
    <type>transmission_interface/SimpleTransmission</type>
    <actuator name="rear_left_wheel_motor">
      <mechanicalReduction>1</mechanicalReduction>
    </actuator>
    <joint name="rear_left_wheel">
      <hardwareInterface>VelocityJointInterface</hardwareInterface>
    </joint>
  </transmission>
  <link name="rear_right_wheel_link">
    <inertial>
      <mass value="2.637" />
      <origin xyz="0 0 0" />
      <inertia ixx="0.02467" ixy="0" ixz="0" iyy="0.02467" iyz="0" izz="0.04411" />
    </inertial>
    <visual>
      <origin rpy="0 0 0" xyz="0 0 0" />
      <geometry>
        <mesh filename="package://husky_description/meshes/wheel.dae" />
      </geometry>
      <material name="DarkGrey"/>
    </visual>
    <collision>
      <origin rpy="1.570795 0 0" xyz="0 0 0" />
      <geometry>
        <cylinder length="0.1143" radius="0.17775" />
      </geometry>
    </collision>
  </link>
  <gazebo reference="rear_right_wheel_link">
    <mu1 value="1.0" />
    <mu2 value="1.0" />
    <kp value="10000000.0" />
    <kd value="1.0" />
    <fdir1 value="1 0 0" />
  </gazebo>
  <joint name="rear_right_wheel" type="continuous">
    <parent link="base_link" />
    <child link="rear_right_wheel_link" />
    <origin rpy="0 0 0" xyz="-0.256 -0.2854 0.03282" />
    <axis rpy="0 0 0" xyz="0 1 0" />
  </joint>
  <transmission name="rear_right_wheel_trans" type="SimpleTransmission">
    <type>transmission_interface/SimpleTransmission</type>
    <actuator name="rear_right_wheel_motor">
      <mechanicalReduction>1</mechanicalReduction>
    </actuator>
    <joint name="rear_right_wheel">
      <hardwareInterface>VelocityJointInterface</hardwareInterface>
    </joint>
  </transmission>
  <!-- Spawn Husky chassis -->
  <link name="top_chassis_link">
    <visual>
      <origin rpy="0 0 0" xyz="0 0 0" />
      <geometry>
        <mesh filename="package://husky_description/meshes/top_chassis.dae" />
      </geometry>
      <material name="yellow"/>
    </visual>
    <inertial>
      <origin xyz="0 0 0" rpy="0 0 0"/>
      <mass value="5.0"/>  <!-- A guess for a medium-sized metal link -->
      <inertia ixx="0.02" ixy="0.0" ixz="0.0" iyy="0.02" iyz="0.0" izz="0.01"/> <!-- Estimated values for a cuboid -->
    </inertial>    
 
  </link>
  <!-- Attach chassis to the robot -->
  <joint name="top_chassis_joint" type="fixed">
    <parent link="base_link" />
    <child link="top_chassis_link" />
  </joint>
  <!-- Spawn front bumper link -->
  <link name="front_bumper_link">
    <visual>
      <geometry>
        <mesh filename="package://husky_description/meshes/bumper.dae" />
      </geometry>
      <material name="DarkGrey"/>
    </visual>
  <inertial>
    <origin xyz="0 0 0" rpy="0 0 0"/>
    <mass value="2.0"/>  <!-- A guess for a medium-sized metal link -->
    <inertia ixx="0.02" ixy="0.0" ixz="0.0" iyy="0.02" iyz="0.0" izz="0.01"/> <!-- Estimated values for a cuboid -->
  </inertial>    
    
    
    
    
  </link>
  <!-- Attach front bumper -->
  <joint name="front_bumper" type="fixed">
    <origin rpy="0 0 0" xyz="0.48 0 0.091" />
    <parent link="base_link" />
    <child link="front_bumper_link" />
  </joint>
  <!-- Spawn rear bumper link -->
  <link name="rear_bumper_link">
    <visual>
      <geometry>
        <mesh filename="package://husky_description/meshes/bumper.dae" />
      </geometry>
      <material name="DarkGrey"/>
    </visual>
  <inertial>
    <origin xyz="0 0 0" rpy="0 0 0"/>
    <mass value="2.0"/>  <!-- A guess for a medium-sized metal link -->
    <inertia ixx="0.02" ixy="0.0" ixz="0.0" iyy="0.02" iyz="0.0" izz="0.01"/> <!-- Estimated values for a cuboid -->
  </inertial>   
   </link>
  <!-- Attach rear bumper -->
  <joint name="rear_bumper" type="fixed">
    <origin rpy="0 0 3.14159" xyz="-0.48 0 0.091" />
    <parent link="base_link" />
    <child link="rear_bumper_link" />
  </joint>
  <!-- Spawn the bulkhead -->
  <link name="dual_arm_bulkhead_link">
    <visual>
      <origin rpy="0 0 0" xyz="0 0 0" />
      <geometry>
        <mesh filename="package://husky_description/meshes/dual_arm_bulkhead.dae" />
      </geometry>
      <material name="dark_grey"/>
    </visual>
    <collision>
      <origin rpy="0 0 0" xyz="0 0 0" />
      <geometry>
        <mesh filename="package://husky_description/meshes/dual_arm_bulkhead.dae" />
      </geometry>
    </collision>
    <inertial>
      <mass value="9.832"/>
      <origin xyz="0 0 0"/>
      <inertia ixx="0.177184" ixy="-0.0045887" ixz="0.003812" iyy="0.752238" iyz="0.004194" izz="0.1376"/>
    </inertial>        
  </link>
  <!-- Attach bulkhead -->
  <joint name="dual_arm_bulkhead_joint" type="fixed">
    <parent link="base_link" />
    <child link="dual_arm_bulkhead_link" />
    <origin rpy="0 0 0" xyz="0 0 0.225" />
  </joint>
  <link name="husky_ptu_pan_link">
    <inertial>
      <mass value="0.65" />
      <origin rpy="0 0 0" xyz="0 0 0" />
      <inertia ixx="0.0001" ixy="0" ixz="0" iyy="0.0001" iyz="0" izz="0.0001" />
    </inertial>
    <visual>
      <material name="ptu_body_color">
        <color rgba="0.3 0.3 0.3 1.0" />
      </material>
      <origin rpy="3.14 0 0" xyz="-0.0295 0.011 0" />
      <geometry>
        <mesh filename="package://flir_ptu_description/meshes/flir-ptu-simple.stl" />
      </geometry>
    </visual>
    <collision>
      <geometry>
        <box size="0.045 0.065 0.044" />
      </geometry>
      <origin xyz="0 0.011 0" />
    </collision>
    <collision>
      <geometry>
        <box size="0.046 0.044 0.044" />
      </geometry>
      <origin xyz="-0.045 0.0215 0" />
    </collision>
    <collision>
      <geometry>
        <cylinder length="0.015" radius="0.005" />
      </geometry>
      <origin rpy="0 1.57 0" xyz="-0.074 0.021 0" />
    </collision>
  </link>
  <gazebo reference="husky_ptu_pan_link">
    <material>Gazebo/DarkGrey</material>
  </gazebo>
  <link name="husky_ptu_tilt_link">
    <inertial>
      <mass value="0.65" />
      <origin rpy="0 0 0" xyz="0 0 0" />
      <inertia ixx="0.0001" ixy="0" ixz="0" iyy="0.0001" iyz="0" izz="0.0001" />
    </inertial>
    <visual>
      <material name="ptu_body_color">
        <color rgba="0.3 0.3 0.3 1.0" />
      </material>
      <origin rpy="3.14 0 0" xyz="-0.0295 0.011 0" />
      <geometry>
        <mesh filename="package://flir_ptu_description/meshes/flir-ptu-simple.stl" />
      </geometry>
    </visual>
    <collision>
      <geometry>
        <box size="0.045 0.065 0.044" />
      </geometry>
      <origin xyz="0 0.011 0" />
    </collision>
    <collision>
      <geometry>
        <box size="0.046 0.044 0.044" />
      </geometry>
      <origin xyz="-0.045 0.0215 0" />
    </collision>
    <collision>
      <geometry>
        <cylinder length="0.015" radius="0.005" />
      </geometry>
      <origin rpy="0 1.57 0" xyz="-0.074 0.021 0" />
    </collision>
  </link>
  <gazebo reference="husky_ptu_tilt_link">
    <material>Gazebo/DarkGrey</material>
  </gazebo>
  <link name="husky_ptu_base_link">
    <inertial>
      <mass value="2e-06" />
      <inertia ixx="1.1e-09" ixy="0" ixz="0" iyy="1.1e-09" iyz="0" izz="1.1e-09" />
    </inertial>
  </link>
  <link name="husky_ptu_tilted_link">
    <inertial>
      <origin xyz="0 0 0" rpy="0 0 0"/>
      <mass value="0.00001"/> <!-- Small non-zero mass -->
      <inertia ixx="0.00000001" ixy="0.0" ixz="0.0" iyy="0.00000001" iyz="0.0" izz="0.00000001"/> <!-- Small non-zero inertia values -->
    </inertial>  
  </link>  
  
  <link name="husky_ptu_mount_link">
    <inertial>
      <mass value="2e-06" />
      <inertia ixx="1.1e-09" ixy="0" ixz="0" iyy="1.1e-09" iyz="0" izz="1.1e-09" />
    </inertial>
  </link>
  <!-- There's an offset between the origin of the pan joint and the origin of 
         the overall device, which is between the mounting screws on its base. -->
  <joint name="husky_ptu_base" type="fixed">
    <parent link="husky_ptu_base_link" />
    <child link="husky_ptu_pan_link" />
    <origin xyz="0 -0.011 0.022" />
  </joint>
  <!-- The pan joint -->
  <joint name="husky_ptu_pan" type="revolute">
    <parent link="husky_ptu_pan_link" />
    <origin rpy="-1.5708 0 0" xyz="0 0 0.066" />
    <child link="husky_ptu_tilt_link" />
    <axis rpy="3.14159 0 0" xyz="0 -1 0" />
    <limit effort="30" lower="-2.775" upper="2.775" velocity="1.0" />
  </joint>
  <transmission name="husky_ptu_pan_trans">
    <type>transmission_interface/SimpleTransmission</type>
    <joint name="husky_ptu_pan">
      <hardwareInterface>PositionJointInterface</hardwareInterface>
    </joint>
    <actuator name="husky_ptu_pan_motor">
      <mechanicalReduction>1</mechanicalReduction>
    </actuator>
  </transmission>
  <!-- The tilt joint -->
  <joint name="husky_ptu_tilt" type="revolute">
    <parent link="husky_ptu_tilt_link" />
    <origin rpy="-1.5708 0 0" xyz="0 0 0" />
    <child link="husky_ptu_tilted_link" />
    <axis xyz="0 1 0" />
    <limit effort="30" lower="-0.82" upper="0.52" velocity="1.0" />
  </joint>
  <transmission name="husky_ptu_tilt_trans">
    <type>transmission_interface/SimpleTransmission</type>
    <joint name="husky_ptu_tilt">
      <hardwareInterface>PositionJointInterface</hardwareInterface>
    </joint>
    <actuator name="husky_ptu_tilt_motor">
      <mechanicalReduction>1</mechanicalReduction>
    </actuator>
  </transmission>
  <!-- Fixed joint to provide a convenient attachment point for accessories. -->
  <joint name="husky_ptu_mount" type="fixed">
    <parent link="husky_ptu_tilted_link" />
    <child link="husky_ptu_mount_link" />
    <origin rpy="3.1416 0 0" xyz="0 0 -0.03912" />
  </joint>
  <!-- Connect PTU to Husky bulkhead -->
  <joint name="husky_ptu_joint" type="fixed">
    <origin rpy="0 0 0" xyz="0.345 0.010414 0.19876" />
    <!-- x-translation still needs to be measured -->
    <parent link="dual_arm_bulkhead_link" />
    <child link="husky_ptu_base_link" />
  </joint>

  <!-- ########################################
       ########### UR5 Left Arm ###############
       ########################################
   -->

  <link name="l_ur5_arm_base_link">
    <visual>
      <geometry>
        <mesh filename="package://ur_description/meshes/ur5/visual/base.dae" />
      </geometry>
      <material name="light_grey" />
    </visual>
    <collision>
      <geometry>
        <mesh filename="package://ur_description/meshes/ur5/collision/base.stl" />
      </geometry>
    </collision>
    <inertial>
      <mass value="4.0" />
      <origin rpy="0 0 0" xyz="0.0 0.0 0.0" />
      <inertia ixx="0.00443333156" ixy="0.0" ixz="0.0" iyy="0.00443333156" iyz="0.0" izz="0.0072" />
    </inertial>
  </link>
  <joint name="l_ur5_arm_shoulder_pan_joint" type="revolute">
    <parent link="l_ur5_arm_base_link" />
    <child link="l_ur5_arm_shoulder_link" />
    <origin rpy="0.0 0.0 0.0" xyz="0.0 0.0 0.089159" />
    <axis xyz="0 0 1" />
    <!-- <limit effort="150.0" lower="-3.14159265" upper="3.14159265" velocity="3.15" /> -->
    <limit effort="150.0" lower="-6.283185307179586" upper="6.283185307179586"
      velocity="3.141592653589793" />
    <dynamics damping="0.0" friction="0.0" />
  </joint>
  <link name="l_ur5_arm_shoulder_link">
    <visual>
      <geometry>
        <mesh filename="package://ur_description/meshes/ur5/visual/shoulder.dae" />
      </geometry>
      <material name="DarkGrey" />
    </visual>
    <collision>
      <geometry>
        <mesh filename="package://ur_description/meshes/ur5/collision/shoulder.stl" />
      </geometry>
    </collision>
    <inertial>
      <mass value="3.7" />
      <origin rpy="0 0 0" xyz="0.0 0.0 0.0" />
      <inertia ixx="0.010267495893" ixy="0.0" ixz="0.0" iyy="0.010267495893" iyz="0.0" izz="0.00666" />
    </inertial>
  </link>
  <joint name="l_ur5_arm_shoulder_lift_joint" type="revolute">
    <parent link="l_ur5_arm_shoulder_link" />
    <child link="l_ur5_arm_upper_arm_link" />
    <origin rpy="0.0 1.570796325 0.0" xyz="0.0 0.13585 0.0" />
    <axis xyz="0 1 0" />
    <!-- <limit effort="2000.0" lower="-3.14159265" upper="3.14159265" velocity="3.15" /> -->
    <!-- <limit effort="150.0" lower="2.7" upper="8.9832" velocity="3.15" /> -->
    <!-- <limit effort="150.0" lower="-3.14159265" upper="3.14159265" velocity="3.15" /> -->
    <limit effort="150.0" lower="-6.283185307179586" upper="6.283185307179586"
      velocity="3.141592653589793" />
    <dynamics damping="0.0" friction="0.0" />
  </joint>
  <link name="l_ur5_arm_upper_arm_link">
    <visual>
      <geometry>
        <mesh filename="package://ur_description/meshes/ur5/visual/upperarm.dae" />
      </geometry>
      <material name="light_grey" />
     </visual>
    <collision>
      <geometry>
        <mesh filename="package://ur_description/meshes/ur5/collision/upperarm.stl" />
      </geometry>
    </collision>
    <inertial>
      <mass value="8.393" />
      <origin rpy="0 0 0" xyz="0.0 0.0 0.28" />
      <inertia ixx="0.22689067591" ixy="0.0" ixz="0.0" iyy="0.22689067591" iyz="0.0" izz="0.0151074" />
    </inertial>
  </link>
  <joint name="l_ur5_arm_elbow_joint" type="revolute">
    <parent link="l_ur5_arm_upper_arm_link" />
    <child link="l_ur5_arm_forearm_link" />
    <origin rpy="0.0 0.0 0.0" xyz="0.0 -0.1197 0.425" />
    <axis xyz="0 1 0" />
    <!-- <limit effort="500.0" lower="-3.14159265" upper="3.14159265" velocity="3.15" /> -->
    <limit effort="150.0" lower="-3.14159265" upper="3.14159265" velocity="3.15" />
    <dynamics damping="0.0" friction="0.0" />
  </joint>
  <link name="l_ur5_arm_forearm_link">
    <visual>
      <geometry>
        <mesh filename="package://ur_description/meshes/ur5/visual/forearm.dae" />
      </geometry>
      <material name="light_grey" />
    </visual>
    <collision>
      <geometry>
        <mesh filename="package://ur_description/meshes/ur5/collision/forearm.stl" />
      </geometry>
    </collision>
    <inertial>
      <mass value="2.275" />
      <origin rpy="0 0 0" xyz="0.0 0.0 0.25" />
      <inertia ixx="0.049443313556" ixy="0.0" ixz="0.0" iyy="0.049443313556" iyz="0.0"
        izz="0.004095" />
    </inertial>
  </link>
  <joint name="l_ur5_arm_wrist_1_joint" type="revolute">
    <parent link="l_ur5_arm_forearm_link" />
    <child link="l_ur5_arm_wrist_1_link" />
    <origin rpy="0.0 1.570796325 0.0" xyz="0.0 0.0 0.39225" />
    <axis xyz="0 1 0" />
    <!-- <limit effort="28.0" lower="-3.14159265" upper="3.14159265" velocity="3.2" /> -->
    <!-- <limit effort="100.0" lower="-3.14159265" upper="3.14159265" velocity="3.2" /> -->
    <limit effort="28.0" lower="-6.283185307179586" upper="6.283185307179586"
      velocity="3.141592653589793" />
    <dynamics damping="0.0" friction="0.0" />
  </joint>
  <link name="l_ur5_arm_wrist_1_link">
    <visual>
      <geometry>
        <mesh filename="package://ur_description/meshes/ur5/visual/wrist1.dae" />
      </geometry>
      <material name="DarkGrey"/>
    </visual>
    <collision>
      <geometry>
        <mesh filename="package://ur_description/meshes/ur5/collision/wrist1.stl" />
      </geometry>
    </collision>
    <inertial>
      <mass value="1.219" />
      <origin rpy="0 0 0" xyz="0.0 0.0 0.0" />
      <inertia ixx="0.111172755531" ixy="0.0" ixz="0.0" iyy="0.111172755531" iyz="0.0" izz="0.21942" />
    </inertial>
  </link>
  <joint name="l_ur5_arm_wrist_2_joint" type="revolute">
    <parent link="l_ur5_arm_wrist_1_link" />
    <child link="l_ur5_arm_wrist_2_link" />
    <origin rpy="0.0 0.0 0.0" xyz="0.0 0.093 0.0" />
    <axis xyz="0 0 1" />
    <!-- <limit effort="28.0" lower="-3.14159265" upper="3.14159265" velocity="3.2" /> -->
    <!-- <limit effort="100.0" lower="-3.14159265" upper="3.14159265" velocity="3.2" /> -->
    <limit effort="28.0" lower="-6.283185307179586" upper="6.283185307179586"
      velocity="3.141592653589793" />
    <dynamics damping="0.0" friction="0.0" />
  </joint>
  <link name="l_ur5_arm_wrist_2_link">
    <visual>
      <geometry>
        <mesh filename="package://ur_description/meshes/ur5/visual/wrist2.dae" />
      </geometry>
      <material name="light_grey" />
    </visual>
    <collision>
      <geometry>
        <mesh filename="package://ur_description/meshes/ur5/collision/wrist2.stl" />
      </geometry>
    </collision>
    <inertial>
      <mass value="1.219" />
      <origin rpy="0 0 0" xyz="0.0 0.0 0.0" />
      <inertia ixx="0.111172755531" ixy="0.0" ixz="0.0" iyy="0.111172755531" iyz="0.0" izz="0.21942" />
    </inertial>
  </link>
  <joint name="l_ur5_arm_wrist_3_joint" type="revolute">
    <parent link="l_ur5_arm_wrist_2_link" />
    <child link="l_ur5_arm_wrist_3_link" />
    <origin rpy="0.0 0.0 0.0" xyz="0.0 0.0 0.09465" />
    <axis xyz="0 1 0" />
    <!-- <limit effort="28.0" lower="-3.14159265" upper="3.14159265" velocity="3.2" /> -->
    <!-- <limit effort="200.0" lower="-3.14159265" upper="3.14159265" velocity="3.2" /> -->
    <!-- <limit effort="5000.0" lower="-3.14159265" upper="3.14159265" velocity="3.2" /> -->
    <!-- <limit effort="200.0" lower="3.0" upper="9.2832" velocity="3.2" /> -->
    <!-- <limit effort="28.0" lower="-3.14159265" upper="3.14159265" velocity="3.2" /> -->
    <limit effort="28.0" lower="-6.283185307179586" upper="6.283185307179586"
      velocity="3.141592653589793" />
    <dynamics damping="0.0" friction="0.0" />
  </joint>
  <link name="l_ur5_arm_wrist_3_link">
    <visual>
      <geometry>
        <mesh filename="package://ur_description/meshes/ur5/visual/wrist3.dae" />
      </geometry>
      <material name="DarkGrey"/>
    </visual>
    <collision>
      <geometry>
        <mesh filename="package://ur_description/meshes/ur5/collision/wrist3.stl" />
      </geometry>
    </collision>
    <inertial>
      <mass value="0.1879" />
      <origin rpy="0 0 0" xyz="0.0 0.0 0.0" />
      <inertia ixx="0.0171364731454" ixy="0.0" ixz="0.0" iyy="0.0171364731454" iyz="0.0"
        izz="0.033822" />
    </inertial>
  </link>
  <joint name="l_ur5_arm_ee_fixed_joint" type="fixed">
    <parent link="l_ur5_arm_wrist_3_link" />
    <child link="l_ur5_arm_ee_link" />
    <origin rpy="0.0 0.0 1.570796325" xyz="0.0 0.0823 0.0" />
  </joint>
  
  
  <link name="l_ur5_arm_ee_link">
    <collision>
      <geometry>
        <box size="0.01 0.01 0.01" />
      </geometry>
      <origin rpy="0 0 0" xyz="-0.01 0 0" />
    </collision>
    <inertial>
      <origin xyz="-0.01 0 0" rpy="0 0 0"/>
      <mass value="0.00001"/> <!-- Small non-zero mass -->
      <inertia ixx="0.167" ixy="0.0" ixz="0.0" iyy="0.167" iyz="0.0" izz="0.167"/>
    </inertial>        
  </link>
    
  <transmission name="l_ur5_arm_shoulder_pan_joint_trans">
    <type>transmission_interface/SimpleTransmission</type>
    <joint name="l_ur5_arm_shoulder_pan_joint">
      <hardwareInterface>hardware_interface/PositionJointInterface</hardwareInterface>
    </joint>
    <actuator name="l_ur5_arm_shoulder_pan_joint_motor">
      <mechanicalReduction>1</mechanicalReduction>
      <!-- <hardwareInterface>hardware_interface/PositionJointInterface</hardwareInterface> -->
    </actuator>
  </transmission>
  <transmission name="l_ur5_arm_shoulder_lift_joint_trans">
    <type>transmission_interface/SimpleTransmission</type>
    <joint name="l_ur5_arm_shoulder_lift_joint">
      <hardwareInterface>hardware_interface/PositionJointInterface</hardwareInterface>
    </joint>
    <actuator name="l_ur5_arm_shoulder_lift_joint_motor">
      <mechanicalReduction>1</mechanicalReduction>
      <!-- <hardwareInterface>hardware_interface/PositionJointInterface</hardwareInterface> -->
    </actuator>
  </transmission>

  <transmission name="l_ur5_arm_elbow_joint_trans">
    <type>transmission_interface/SimpleTransmission</type>
    <joint name="l_ur5_arm_elbow_joint">
      <hardwareInterface>hardware_interface/PositionJointInterface</hardwareInterface>
    </joint>
    <actuator name="l_ur5_arm_elbow_joint_motor">
      <mechanicalReduction>1</mechanicalReduction>
      <!-- <hardwareInterface>hardware_interface/PositionJointInterface</hardwareInterface> -->
    </actuator>
  </transmission>
  <transmission name="l_ur5_arm_wrist_1_trans">
    <type>transmission_interface/SimpleTransmission</type>
    <joint name="l_ur5_arm_wrist_1_joint">
      <hardwareInterface>hardware_interface/PositionJointInterface</hardwareInterface>
    </joint>
    <actuator name="l_ur5_arm_wrist_1_motor">
      <mechanicalReduction>1</mechanicalReduction>
      <!-- <hardwareInterface>hardware_interface/PositionJointInterface</hardwareInterface> -->
    </actuator>
  </transmission>
  <transmission name="l_ur5_arm_wrist_2_trans">
    <type>transmission_interface/SimpleTransmission</type>
    <joint name="l_ur5_arm_wrist_2_joint">
      <hardwareInterface>hardware_interface/PositionJointInterface</hardwareInterface>
    </joint>
    <actuator name="l_ur5_arm_wrist_2_motor">
      <mechanicalReduction>1</mechanicalReduction>
      <!-- <hardwareInterface>hardware_interface/PositionJointInterface</hardwareInterface> -->
    </actuator>
  </transmission>
  <transmission name="l_ur5_arm_wrist_3_trans">
    <type>transmission_interface/SimpleTransmission</type>
    <joint name="l_ur5_arm_wrist_3_joint">
      <hardwareInterface>hardware_interface/PositionJointInterface</hardwareInterface>
    </joint>
    <actuator name="l_ur5_arm_wrist_3_motor">
      <mechanicalReduction>1</mechanicalReduction>
      <!-- <hardwareInterface>hardware_interface/PositionJointInterface</hardwareInterface> -->
    </actuator>
  </transmission>
  <!-- nothing to do here at the moment -->
  <!-- ROS base_link to UR 'Base' Coordinates transform -->
  <link name="l_ur5_arm_base">
    <inertial>
      <origin xyz="0 0 0" rpy="0 0 0"/>
      <mass value="0.00001"/> <!-- Small non-zero mass -->
      <inertia ixx="0.00000001" ixy="0.0" ixz="0.0" iyy="0.00000001" iyz="0.0" izz="0.00000001"/> <!-- Small non-zero inertia values -->
    </inertial>    
  </link>
  
  <joint name="l_ur5_arm_base_link_base_fixed_joint" type="fixed">
    <!-- NOTE: this rotation is only needed as long as base_link itself is
                 not corrected wrt the real robot (ie: rotated over 180
                 degrees)
      -->
    <origin rpy="0 0 -3.14159265" xyz="0 0 0.0" />
    <parent link="l_ur5_arm_base_link" />
    <child link="l_ur5_arm_base" />
  </joint>
  <!-- Frame coincident with all-zeros TCP on UR controller -->
  <link name="l_ur5_arm_tool0">
     <inertial>
      <origin xyz="0 0 0" rpy="0 0 0"/>
      <mass value="0.00001"/> <!-- Small non-zero mass -->
      <inertia ixx="0.00000001" ixy="0.0" ixz="0.0" iyy="0.00000001" iyz="0.0" izz="0.00000001"/> <!-- Small non-zero inertia values -->
    </inertial>    
  </link> 
  
  
  
  <joint name="l_ur5_arm_wrist_3_link_tool0_fixed_joint" type="fixed">
    <origin rpy="-1.570796325 0 0" xyz="0 0.0823 0" />
    <parent link="l_ur5_arm_wrist_3_link" />
    <child link="l_ur5_arm_tool0" />
  </joint>

  <link name="l_tcp">
      <inertial>
      <origin xyz="0 0 0" rpy="0 0 0"/>
      <mass value="0.00001"/> <!-- Small non-zero mass -->
      <inertia ixx="0.00000001" ixy="0.0" ixz="0.0" iyy="0.00000001" iyz="0.0" izz="0.00000001"/> <!-- Small non-zero inertia values -->
    </inertial>    
  </link>  
  
  
  
  <joint name="l_ur5_arm_tool0_to_l_tcp_fixed_joint" type="fixed">
    <origin rpy="0 -1.570796325 0" xyz="0 0 0" />
    <parent link="l_ur5_arm_tool0" />
    <child link="l_tcp" />
  </joint>


  <joint name="l_ur5_arm_base" type="fixed">
    <parent link="dual_arm_bulkhead_link" />
    <child link="l_ur5_arm_base_link" />
    <origin rpy="0 -0.785 -1.57" xyz="0.125 0.15 0.135" />
  </joint>


  <!-- ########################################
       ########### UR5 Right Arm ##############
       ########################################
   -->
  <link name="r_ur5_arm_base_link">
    <visual>
      <geometry>
        <mesh filename="package://ur_description/meshes/ur5/visual/base.dae" />
      </geometry>
      <material name="light_grey" />
    </visual>
    <collision>
      <geometry>
        <mesh filename="package://ur_description/meshes/ur5/collision/base.stl" />
      </geometry>
    </collision>
    <inertial>
      <mass value="4.0" />
      <origin rpy="0 0 0" xyz="0.0 0.0 0.0" />
      <inertia ixx="0.00443333156" ixy="0.0" ixz="0.0" iyy="0.00443333156" iyz="0.0" izz="0.0072" />
    </inertial>
  </link>
  <joint name="r_ur5_arm_shoulder_pan_joint" type="revolute">
    <parent link="r_ur5_arm_base_link" />
    <child link="r_ur5_arm_shoulder_link" />
    <origin rpy="0.0 0.0 0.0" xyz="0.0 0.0 0.089159" />
    <axis xyz="0 0 1" />
    <!-- <limit effort="150.0" lower="-3.14159265" upper="3.14159265" velocity="3.15" /> -->
    <limit effort="150.0" lower="-6.283185307179586" upper="6.283185307179586"
      velocity="3.141592653589793" />
    <dynamics damping="0.0" friction="0.0" />
  </joint>
  <link name="r_ur5_arm_shoulder_link">
    <visual>
      <geometry>
        <mesh filename="package://ur_description/meshes/ur5/visual/shoulder.dae" />
      </geometry>
      <material name="DarkGrey" />
    </visual>
    <collision>
      <geometry>
        <mesh filename="package://ur_description/meshes/ur5/collision/shoulder.stl" />
      </geometry>
    </collision>
    <inertial>
      <mass value="3.7" />
      <origin rpy="0 0 0" xyz="0.0 0.0 0.0" />
      <inertia ixx="0.010267495893" ixy="0.0" ixz="0.0" iyy="0.010267495893" iyz="0.0" izz="0.00666" />
    </inertial>
  </link>
  <joint name="r_ur5_arm_shoulder_lift_joint" type="revolute">
    <parent link="r_ur5_arm_shoulder_link" />
    <child link="r_ur5_arm_upper_arm_link" />
    <origin rpy="0.0 1.570796325 0.0" xyz="0.0 0.13585 0.0" />
    <axis xyz="0 1 0" />
    <!-- <limit effort="150.0" lower="-3.14159265" upper="3.14159265" velocity="3.15" /> -->
    <limit effort="150.0" lower="-6.283185307179586" upper="6.283185307179586"
      velocity="3.141592653589793" />
    <dynamics damping="0.0" friction="0.0" />
  </joint>
  <link name="r_ur5_arm_upper_arm_link">
    <visual>
      <geometry>
        <mesh filename="package://ur_description/meshes/ur5/visual/upperarm.dae" />
      </geometry>
      <material name="light_grey" />
    </visual>
    <collision>
      <geometry>
        <mesh filename="package://ur_description/meshes/ur5/collision/upperarm.stl" />
      </geometry>
    </collision>
    <inertial>
      <mass value="8.393" />
      <origin rpy="0 0 0" xyz="0.0 0.0 0.28" />
      <inertia ixx="0.22689067591" ixy="0.0" ixz="0.0" iyy="0.22689067591" iyz="0.0" izz="0.0151074" />
    </inertial>
  </link>
  <joint name="r_ur5_arm_elbow_joint" type="revolute">
    <parent link="r_ur5_arm_upper_arm_link" />
    <child link="r_ur5_arm_forearm_link" />
    <origin rpy="0.0 0.0 0.0" xyz="0.0 -0.1197 0.425" />
    <axis xyz="0 1 0" />
    <!-- <limit effort="150.0" lower="-3.14159265" upper="3.14159265" velocity="3.15" /> -->
    <limit effort="150.0" lower="-3.141592653589793" upper="3.141592653589793"
      velocity="3.141592653589793" />
    <dynamics damping="0.0" friction="0.0" />
  </joint>
  <link name="r_ur5_arm_forearm_link">
    <visual>
      <geometry>
        <mesh filename="package://ur_description/meshes/ur5/visual/forearm.dae" />
      </geometry>
      <material name="light_grey" />
    </visual>
    <collision>
      <geometry>
        <mesh filename="package://ur_description/meshes/ur5/collision/forearm.stl" />
      </geometry>
    </collision>
    <inertial>
      <mass value="2.275" />
      <origin rpy="0 0 0" xyz="0.0 0.0 0.25" />
      <inertia ixx="0.049443313556" ixy="0.0" ixz="0.0" iyy="0.049443313556" iyz="0.0"
        izz="0.004095" />
    </inertial>
  </link>
  <joint name="r_ur5_arm_wrist_1_joint" type="revolute">
    <parent link="r_ur5_arm_forearm_link" />
    <child link="r_ur5_arm_wrist_1_link" />
    <origin rpy="0.0 1.570796325 0.0" xyz="0.0 0.0 0.39225" />
    <axis xyz="0 1 0" />
    <!-- <limit effort="28.0" lower="-3.14159265" upper="3.14159265" velocity="3.2" /> -->
    <limit effort="28.0" lower="-6.283185307179586" upper="6.283185307179586"
      velocity="3.141592653589793" />
    <dynamics damping="0.0" friction="0.0" />
  </joint>
  <link name="r_ur5_arm_wrist_1_link">
    <visual>
      <geometry>
        <mesh filename="package://ur_description/meshes/ur5/visual/wrist1.dae" />
      </geometry>
      <material name="DarkGrey" />
    </visual>
    <collision>
      <geometry>
        <mesh filename="package://ur_description/meshes/ur5/collision/wrist1.stl" />
      </geometry>
    </collision>
    <inertial>
      <mass value="1.219" />
      <origin rpy="0 0 0" xyz="0.0 0.0 0.0" />
      <inertia ixx="0.111172755531" ixy="0.0" ixz="0.0" iyy="0.111172755531" iyz="0.0" izz="0.21942" />
    </inertial>
  </link>
  <joint name="r_ur5_arm_wrist_2_joint" type="revolute">
    <parent link="r_ur5_arm_wrist_1_link" />
    <child link="r_ur5_arm_wrist_2_link" />
    <origin rpy="0.0 0.0 0.0" xyz="0.0 0.093 0.0" />
    <axis xyz="0 0 1" />
    <!-- <limit effort="28.0" lower="-3.14159265" upper="3.14159265" velocity="3.2" /> -->
    <limit effort="28.0" lower="-6.283185307179586" upper="6.283185307179586"
      velocity="3.141592653589793" />
    <dynamics damping="0.0" friction="0.0" />
  </joint>
  <link name="r_ur5_arm_wrist_2_link">
    <visual>
      <geometry>
        <mesh filename="package://ur_description/meshes/ur5/visual/wrist2.dae" />
      </geometry>
      <material name="light_grey" />
    </visual>
    <collision>
      <geometry>
        <mesh filename="package://ur_description/meshes/ur5/collision/wrist2.stl" />
      </geometry>
    </collision>
    <inertial>
      <mass value="1.219" />
      <origin rpy="0 0 0" xyz="0.0 0.0 0.0" />
      <inertia ixx="0.111172755531" ixy="0.0" ixz="0.0" iyy="0.111172755531" iyz="0.0" izz="0.21942" />
    </inertial>
  </link>
  <joint name="r_ur5_arm_wrist_3_joint" type="revolute">
    <parent link="r_ur5_arm_wrist_2_link" />
    <child link="r_ur5_arm_wrist_3_link" />
    <origin rpy="0.0 0.0 0.0" xyz="0.0 0.0 0.09465" />
    <axis xyz="0 1 0" />
    <!-- <limit effort="28.0" lower="-3.14159265" upper="3.14159265" velocity="3.2" /> -->
    <limit effort="28.0" lower="-6.283185307179586" upper="6.283185307179586"
      velocity="3.141592653589793" />
    <dynamics damping="0.0" friction="0.0" />
  </joint>
  <link name="r_ur5_arm_wrist_3_link">
    <visual>
      <geometry>
        <mesh filename="package://ur_description/meshes/ur5/visual/wrist3.dae" />
      </geometry>
      <material name="DarkGrey" />
    </visual>
    <collision>
      <geometry>
        <mesh filename="package://ur_description/meshes/ur5/collision/wrist3.stl" />
      </geometry>
    </collision>
    <inertial>
      <mass value="0.1879" />
      <origin rpy="0 0 0" xyz="0.0 0.0 0.0" />
      <inertia ixx="0.0171364731454" ixy="0.0" ixz="0.0" iyy="0.0171364731454" iyz="0.0"
        izz="0.033822" />
    </inertial>
  </link>
  <joint name="r_ur5_arm_ee_fixed_joint" type="fixed">
    <parent link="r_ur5_arm_wrist_3_link" />
    <child link="r_ur5_arm_ee_link" />
    <origin rpy="0.0 0.0 1.570796325" xyz="0.0 0.0823 0.0" />
  </joint>
  
  <link name="r_ur5_arm_ee_link">
      <visual>
      <geometry>
        <box size="0.01 0.01 0.01" />
      </geometry>
      <material name="black" />
    </visual>

    <collision>
      <geometry>
        <box size="0.01 0.01 0.01" />
      </geometry>
      <origin rpy="0 0 0" xyz="-0.01 0 0" />
    </collision>
    <inertial>
      <origin xyz="0 0 0" rpy="0 0 0"/>
      <mass value="0.00001"/> <!-- Small non-zero mass -->
      <inertia ixx="0.167" ixy="0.0" ixz="0.0" iyy="0.167" iyz="0.0" izz="0.167"/>
    </inertial>        
  </link>
  
  <transmission name="r_ur5_arm_shoulder_pan_trans">
    <type>transmission_interface/SimpleTransmission</type>
    <joint name="r_ur5_arm_shoulder_pan_joint">
      <hardwareInterface>hardware_interface/PositionJointInterface</hardwareInterface>
    </joint>
    <actuator name="r_ur5_arm_shoulder_pan_motor">
      <mechanicalReduction>1</mechanicalReduction>
      <hardwareInterface>hardware_interface/PositionJointInterface</hardwareInterface>
    </actuator>
  </transmission>
  <transmission name="r_ur5_arm_shoulder_lift_trans">
    <type>transmission_interface/SimpleTransmission</type>
    <joint name="r_ur5_arm_shoulder_lift_joint">
      <hardwareInterface>hardware_interface/PositionJointInterface</hardwareInterface>
    </joint>
    <actuator name="r_ur5_arm_shoulder_lift_motor">
      <mechanicalReduction>1</mechanicalReduction>
      <hardwareInterface>hardware_interface/PositionJointInterface</hardwareInterface>
    </actuator>
  </transmission>
  <transmission name="r_ur5_arm_elbow_trans">
    <type>transmission_interface/SimpleTransmission</type>
    <joint name="r_ur5_arm_elbow_joint">
      <hardwareInterface>hardware_interface/PositionJointInterface</hardwareInterface>
    </joint>
    <actuator name="r_ur5_arm_elbow_motor">
      <mechanicalReduction>1</mechanicalReduction>
      <hardwareInterface>hardware_interface/PositionJointInterface</hardwareInterface>
    </actuator>
  </transmission>
  <transmission name="r_ur5_arm_wrist_1_trans">
    <type>transmission_interface/SimpleTransmission</type>
    <joint name="r_ur5_arm_wrist_1_joint">
      <hardwareInterface>hardware_interface/PositionJointInterface</hardwareInterface>
    </joint>
    <actuator name="r_ur5_arm_wrist_1_motor">
      <mechanicalReduction>1</mechanicalReduction>
      <hardwareInterface>hardware_interface/PositionJointInterface</hardwareInterface>
    </actuator>
  </transmission>
  <transmission name="r_ur5_arm_wrist_2_trans">
    <type>transmission_interface/SimpleTransmission</type>
    <joint name="r_ur5_arm_wrist_2_joint">
      <hardwareInterface>hardware_interface/PositionJointInterface</hardwareInterface>
    </joint>
    <actuator name="r_ur5_arm_wrist_2_motor">
      <mechanicalReduction>1</mechanicalReduction>
      <hardwareInterface>hardware_interface/PositionJointInterface</hardwareInterface>
    </actuator>
  </transmission>
  <transmission name="r_ur5_arm_wrist_3_trans">
    <type>transmission_interface/SimpleTransmission</type>
    <joint name="r_ur5_arm_wrist_3_joint">
      <hardwareInterface>hardware_interface/PositionJointInterface</hardwareInterface>
    </joint>
    <actuator name="r_ur5_arm_wrist_3_motor">
      <mechanicalReduction>1</mechanicalReduction>
      <hardwareInterface>hardware_interface/PositionJointInterface</hardwareInterface>
    </actuator>
  </transmission>

  <!-- nothing to do here at the moment -->
  <!-- ROS base_link to UR 'Base' Coordinates transform -->
  <link name="r_ur5_arm_base">
    <inertial>
      <origin xyz="0 0 0" rpy="0 0 0"/>
      <mass value="0.00001"/> <!-- Small non-zero mass -->
      <inertia ixx="0.00000001" ixy="0.0" ixz="0.0" iyy="0.00000001" iyz="0.0" izz="0.00000001"/> <!-- Small non-zero inertia values -->
    </inertial>
  </link>  
    
  
  <joint name="r_ur5_arm_base_link_base_fixed_joint" type="fixed">
    <!-- NOTE: this rotation is only needed as long as base_link itself is
                 not corrected wrt the real robot (ie: rotated over 180
                 degrees)
      -->
    <origin rpy="0 0 -3.14159265" xyz="0 0 0" />
    <parent link="r_ur5_arm_base_link" />
    <child link="r_ur5_arm_base" />
  </joint>
  <!-- Frame coincident with all-zeros TCP on UR controller -->
  <link name="r_ur5_arm_tool0">
    <inertial>
      <origin xyz="0 0 0" rpy="0 0 0"/>
      <mass value="0.00001"/> <!-- Small non-zero mass -->
      <inertia ixx="0.00000001" ixy="0.0" ixz="0.0" iyy="0.00000001" iyz="0.0" izz="0.00000001"/> <!-- Small non-zero inertia values -->
    </inertial>
  </link>  
  <joint name="r_ur5_arm_wrist_3_link_tool0_fixed_joint" type="fixed">
    <origin rpy="-1.570796325 0 0" xyz="0 0.0823 0" />
    <parent link="r_ur5_arm_wrist_3_link" />
    <child link="r_ur5_arm_tool0" />
  </joint>

  <link name="r_tcp" >
    <inertial>
      <origin xyz="0 0 0" rpy="0 0 0"/>
      <mass value="0.00001"/> <!-- Small non-zero mass -->
      <inertia ixx="0.00000001" ixy="0.0" ixz="0.0" iyy="0.00000001" iyz="0.0" izz="0.00000001"/> <!-- Small non-zero inertia values -->
    </inertial>
  </link>   
  
  
  <joint name="r_ur5_arm_tool0_to_r_tcp_fixed_joint" type="fixed">
    <origin rpy="0 -1.570796325 0" xyz="0 0 0" />
    <parent link="r_ur5_arm_tool0" />
    <child link="r_tcp" />
  </joint>


  <!-- Add bumblebee camera -->
  <link name="bumblebee2">
    <visual>
      <origin rpy="-1.5707 0 -1.5707" xyz="0 0 0" />
      <geometry>
        <mesh filename="package://pointgrey_camera_description/meshes/pointgrey_bumblebee2.dae" />
      </geometry>
      <material name="light_grey" />
    </visual>
    
    <collision>
      <origin rpy="0 0 0" xyz="0 0 0" />
      <geometry>
        <box size="0.04740 0.157 0.036" />
      </geometry>
    </collision>
    <inertial>
      <mass value="0.342" />
      <inertia ixx="0.00010096866" ixy="0" ixz="0" iyy="0.00076652916" iyz="0" izz="0.0007394325" />
    </inertial>
  </link>
  <link name="bumblebee2_optical">
    <inertial>
      <mass value="1E-5" />
      <inertia ixx="1E-10" ixy="0" ixz="0" iyy="1E-10" iyz="0" izz="1E-10" />
    </inertial>
  </link>
  <joint name="bumblebee2_optical_joint" type="fixed">
    <origin rpy="-1.570796 0 -1.570796" xyz="0 0 0" />
    <parent link="bumblebee2" />
    <child link="bumblebee2_optical" />
  </joint>
  <gazebo reference="bumblebee2_optical">
    <sensor name="stereo_camera" type="multicamera">
      <update_rate>20</update_rate>
      <camera name="left">
        <pose>0 0 0 0 -1.5707 1.5707</pose>
        <horizontal_fov>1.15191730632</horizontal_fov>
        <image>
          <width>1024</width>
          <height>768</height>
          <format>R8G8B8</format>
        </image>
        <clip>
          <near>0.5</near>
          <far>300</far>
        </clip>
        <noise>
          <type>gaussian</type>
          <mean>0.0</mean>
          <stddev>0.007</stddev>
        </noise>
      </camera>
      <camera name="right">
        <pose>0.12 0 0 0 -1.5707 1.5707</pose>
        <horizontal_fov>1.15191730632</horizontal_fov>
        <image>
          <width>1024</width>
          <height>768</height>
          <format>R8G8B8</format>
        </image>
        <clip>
          <near>0.5</near>
          <far>300</far>
        </clip>
        <noise>
          <type>gaussian</type>
          <mean>0.0</mean>
          <stddev>0.007</stddev>
        </noise>
      </camera>
      <plugin filename="libgazebo_ros_multicamera.so" name="stereo_camera_controller">
        <alwaysOn>true</alwaysOn>
        <cameraName>bumblebee2</cameraName>
        <imageTopicName>image_raw</imageTopicName>
        <cameraInfoTopicName>camera_info</cameraInfoTopicName>
        <frameName>bumblebee2_optical</frameName>
        <hackBaseline>0.12</hackBaseline>
        <!-- NOTE: Distortion is currently unused -->
        <distortionK1>0.0</distortionK1>
        <distortionK2>0.0</distortionK2>
        <distortionK3>0.0</distortionK3>
        <distortionT1>0.0</distortionT1>
        <distortionT2>0.0</distortionT2>
      </plugin>
    </sensor>
  </gazebo>
  <joint name="bumblebee2_mount_joint" type="fixed">
    <origin rpy="0 0 0" xyz="0 0 0.02224" />
    <parent link="husky_ptu_mount_link" />
    <child link="bumblebee2" />
  </joint>
  <!-- Add force torque model FT300 -->
  <!-- mount the fts to the robot -->
  <joint name="l_robotiq_fts300_fts_fix" type="fixed">
    <!--In
    most cases origin would be flange adapter plate: <origin xyz="0 0 0.009" rpy="0 0 0"/> /-->
    <origin rpy="0 1.57 0" xyz="0 0 0" />
    <parent link="l_ur5_arm_ee_link" />
    <child link="l_robotiq_fts300_fts_robotside" />
  </joint>
  <link name="l_robotiq_fts300_fts_robotside">
    <inertial>
      <origin rpy="0 0 0" xyz="0 0 0.01875" />
      <mass value="0.65" />
      <inertia ixx="0.000661171875" ixy="0" ixz="0" iyy="0.000661171875" iyz="0" izz="0.00117" />
    </inertial>
    <visual>
      <origin rpy="0 0 0" xyz="0 0 0" />
      <geometry>
        <mesh
          filename="package://robotiq_force_torque_sensor/meshes/visual/robotiq_fts300.dae" />
      </geometry>
      <material name="black" />
    </visual>
    <collision>
      <origin rpy="0 0 0" xyz="0 0 0" />
      <geometry>
        <mesh
          filename="package://robotiq_force_torque_sensor/meshes/collision/robotiq_fts300.dae" />
      </geometry>
    </collision>
  </link>
  <!-- virtual measurement frame -->
  <joint name="l_robotiq_fts300_measurment_joint" type="fixed">
    <origin rpy="0 0 0" xyz="0 0 0.01625" />
    <parent link="l_robotiq_fts300_fts_robotside" />
    <child link="l_robotiq_fts300_robotiq_force_torque_frame_id" />
  </joint>
  <link name="l_robotiq_fts300_robotiq_force_torque_frame_id">
    <inertial>
      <origin xyz="0 0 0" rpy="0 0 0"/>
      <mass value="0.00001"/> <!-- Small non-zero mass -->
      <inertia ixx="0.00000001" ixy="0.0" ixz="0.0" iyy="0.00000001" iyz="0.0" izz="0.00000001"/> <!-- Small non-zero inertia values -->
    </inertial>
  </link>
   
  
  
  <!-- toolside frame -->
  <joint name="l_robotiq_fts300_toolside_joint" type="fixed">
    <origin rpy="0 0 0" xyz="0 0 0.0375" />
    <parent link="l_robotiq_fts300_fts_robotside" />
    <child link="l_robotiq_fts300_fts_toolside" />
  </joint>
  <link name="l_robotiq_fts300_fts_toolside" >
    <inertial>
      <origin xyz="0 0 0" rpy="0 0 0"/>
      <mass value="0.00001"/> <!-- Small non-zero mass -->
      <inertia ixx="0.00000001" ixy="0.0" ixz="0.0" iyy="0.00000001" iyz="0.0" izz="0.00000001"/> <!-- Small non-zero inertia values -->
    </inertial>
  </link>

  <!-- mount the fts to the robot -->
  <joint name="r_robotiq_fts300_fts_fix" type="fixed">
    <!--In
    most cases origin would be flange adapter plate: <origin xyz="0 0 0.009" rpy="0 0 0"/> /-->
    <origin rpy="0 1.57 0" xyz="0 0 0" />
    <parent link="r_ur5_arm_ee_link" />
    <child link="r_robotiq_fts300_fts_robotside" />
  </joint>
  <link name="r_robotiq_fts300_fts_robotside">
    <inertial>
      <origin rpy="0 0 0" xyz="0 0 0.01875" />
      <mass value="0.65" />
      <inertia ixx="0.000661171875" ixy="0" ixz="0" iyy="0.000661171875" iyz="0" izz="0.00117" />
    </inertial>
    <visual>
      <origin rpy="0 0 0" xyz="0 0 0" />
      <geometry>
        <mesh
          filename="package://robotiq_force_torque_sensor/meshes/visual/robotiq_fts300.dae" />
      </geometry>
      <material name="black" />
    </visual>
    <collision>
      <origin rpy="0 0 0" xyz="0 0 0" />
      <geometry>
        <mesh
          filename="package://robotiq_force_torque_sensor/meshes/collision/robotiq_fts300.dae" />
      </geometry>
    </collision>
  </link>
  <!-- virtual measurement frame -->
  <joint name="r_robotiq_fts300_measurment_joint" type="fixed">
    <origin rpy="0 0 0" xyz="0 0 0.01625" />
    <parent link="r_robotiq_fts300_fts_robotside" />
    <child link="r_robotiq_fts300_robotiq_force_torque_frame_id" />
  </joint>
  <link name="r_robotiq_fts300_robotiq_force_torque_frame_id">
    <inertial>
      <origin xyz="0 0 0" rpy="0 0 0"/>
      <mass value="0.00001"/> <!-- Small non-zero mass -->
      <inertia ixx="0.00000001" ixy="0.0" ixz="0.0" iyy="0.00000001" iyz="0.0" izz="0.00000001"/> <!-- Small non-zero inertia values -->
    </inertial>
  </link>  
    
  <!-- toolside frame -->
  <joint name="r_robotiq_fts300_toolside_joint" type="fixed">
    <origin rpy="0 0 0" xyz="0 0 0.0375" />
    <parent link="r_robotiq_fts300_fts_robotside" />
    <child link="r_robotiq_fts300_fts_toolside" />
  </joint>
  <link name="r_robotiq_fts300_fts_toolside">
    <inertial>
      <origin xyz="0 0 0" rpy="0 0 0"/>
      <mass value="0.00001"/> <!-- Small non-zero mass -->
      <inertia ixx="0.00000001" ixy="0.0" ixz="0.0" iyy="0.00000001" iyz="0.0" izz="0.00000001"/> <!-- Small non-zero inertia values -->
    </inertial>
  </link>    
  
  
  <!-- joint attaching parent link to robotiq hand -->


  <joint name="r_ur5_arm_base" type="fixed">
    <parent link="dual_arm_bulkhead_link" />
    <child link="r_ur5_arm_base_link" />
    <origin rpy="0 0.785 -1.57" xyz="0.125 -0.15 0.135" />
  </joint>


  <!-- Insert the fingers -->
  <!-- Link list -->
  <!-- Link 0 -->

  <!-- End of link list -->
  <!-- Joint list -->
  <!-- Joint proximal actuating hinge -->

  <!-- end of joint list -->
  <!-- joint attaching parent link to robotiq hand -->
  <!-- ########################################
       ########### Right Finger ###############
       ########################################
   -->


  <!-- ################################### -->
  <!-- ### Schunk hand right          #### -->
  <!-- ################################### -->

  <joint name="r_robotiq_hand_joint" type="fixed">
    <origin rpy="0.0 0 1.0" xyz="0 0 0.0001" />
    <parent link="r_robotiq_fts300_fts_toolside" />
    <child link="right_schunk_base_link" />
  </joint>  
  
  <link name="right_schunk_base_link">
    <inertial>
      <origin xyz="0 0 0" rpy="0 0 0"/>
      <mass value="0.00001"/> <!-- Small non-zero mass -->
      <inertia ixx="0.00000001" ixy="0.0" ixz="0.0" iyy="0.00000001" iyz="0.0" izz="0.00000001"/> <!-- Small non-zero inertia values -->
    </inertial>
  </link>  
    
  <!-- RIGHT HAND = 1, LEFT HAND = -1 -->
  <!-- BASE_LINE LINKS -->  <!-- BASE_LINE LINKS -->  <!-- BASE_LINE LINKS -->  <!-- BASE_LINE LINKS -->  <!-- BASE_LINE LINKS -->  <!-- BASE_LINE LINKS -->  <!-- BASE_LINE LINKS -->
  <joint name="right_hand_base_joint" type="fixed">
    <origin rpy="0 0 0" xyz="0 0 0"/>
    <parent link="right_schunk_base_link"/>
    <child link="right_hand_base_link"/>
  </joint>
  <link name="right_hand_base_link">				<!-- base of the hand -->
    <origin rpy="0 0 0" xyz="0 0 0"/>
    <visual>
      <origin rpy="0 0 0" xyz="0 0 0"/>
      <geometry>
        <mesh filename="package://schunk_svh_description/meshes/base10.dae"/>
      </geometry>
      <material name="light_grey"/> 
    </visual>
    <collision>
      <origin rpy="0 0 0" xyz="0 0 0"/>
      <geometry>
        <mesh filename="package://schunk_svh_description/meshes/base10.dae"/>
      </geometry>
    </collision>
    <inertial>
      <mass value="0.57743"/>
      <origin xyz="0.0 -2.3e-05 0.139371"/>
      <inertia ixx="0.04725" ixy="-0.0" ixz="-0.0" iyy="0.04717" iyz="0.0" izz="0.07606"/>
    </inertial>
  </link>
  <link name="right_hand_d">
    <inertial>
      <mass value="0.01"/>
      <origin xyz="0 0 0"/>
      <inertia ixx="0.001" ixy="0.0" ixz="0.0" iyy="0.001" iyz="0.0" izz="0.001"/>
    </inertial>
  </link>
  <link name="right_hand_h">
    <inertial>
      <mass value="0.01"/>
      <origin xyz="0 0 0"/>
      <inertia ixx="0.001" ixy="0.0" ixz="0.0" iyy="0.001" iyz="0.0" izz="0.001"/>
    </inertial>
  </link>
  <link name="right_hand_d2">
    <inertial>
      <mass value="0.01"/>
      <origin xyz="0 0 0"/>
      <inertia ixx="0.001" ixy="0.0" ixz="0.0" iyy="0.001" iyz="0.0" izz="0.001"/>
    </inertial>
  </link>
  <!-- LENGTH NOT FOUND IN DATASHEET! GUESSED!!! -->
  <link name="right_hand_e1">									<!-- palm: left half -->
    <visual>
      <origin rpy="0 0 0" xyz="0 0.01313 0"/>
      <geometry>
        <mesh filename="package://schunk_svh_description/meshes/h10.dae" scale="1 1 1"/>
      </geometry>
      <material name="DarkGrey" />
    </visual>
    <collision>
      <origin rpy="0 0 0" xyz="0 0.01313 0"/>
      <geometry>
        <mesh filename="package://schunk_svh_description/meshes/h10.dae" scale="1 1 1"/>
      </geometry>
    </collision>
    <inertial>
      <mass value="0.01"/>
      <origin xyz="0 0 0"/>
      <inertia ixx="0.001" ixy="0.0" ixz="0.0" iyy="0.001" iyz="0.0" izz="0.001"/>
    </inertial>
  </link>
  <!-- LENGTH NOT FOUND IN DATASHEET! GUESSED!!! -->
  <link name="right_hand_e2">									<!-- palm: right half -->
    <visual>
      <origin xyz="-0.0007 0 -0.01002"/>
      <geometry>
        <mesh filename="package://schunk_svh_description/meshes/h11.dae" scale="1 1 1"/>
      </geometry>
      <material name="DarkGrey" />
    </visual>
    <collision>
      <origin xyz="-0.0007 0 -0.01002"/>
      <geometry>
        <mesh filename="package://schunk_svh_description/meshes/h11.dae" scale="1 1 1"/>
      </geometry>
    </collision>
    <inertial>
      <mass value="0.46184"/>
      <origin xyz="0.145071 -0.037868 0.323449"/>
      <inertia ixx="0.01908" ixy="-0.00121" ixz="-0.00011" iyy="0.01704" iyz="0.00277" izz="0.00862"/>
    </inertial>
  </link>
  <!-- LENGTH NOT FOUND IN DATASHEET! GUESSED!!! -->
  <link name="right_hand_e3">
    <inertial>
      <mass value="0.01"/>
      <origin xyz="0 0 0"/>
      <inertia ixx="0.001" ixy="0.0" ixz="0.0" iyy="0.001" iyz="0.0" izz="0.001"/>
    </inertial>
  </link>
  <link name="right_hand_e">
    <inertial>
      <origin xyz="0 0 0" rpy="0 0 0"/>
      <mass value="0.00001"/> <!-- Small non-zero mass -->
      <inertia ixx="0.00000001" ixy="0.0" ixz="0.0" iyy="0.00000001" iyz="0.0" izz="0.00000001"/> <!-- Small non-zero inertia values -->
    </inertial>  
  </link>
  <!-- LENGTH NOT FOUND IN DATASHEET! GUESSED, BUT POSITION CALCULATED: E4 = D-G-F!!! -->
  <link name="right_hand_e4">
    <inertial>
      <mass value="0.01"/>
      <origin xyz="0 0 0"/>
      <inertia ixx="0.001" ixy="0.0" ixz="0.0" iyy="0.001" iyz="0.0" izz="0.001"/>
    </inertial>
  </link>
  <!-- LENGTH NOT FOUND IN DATASHEET! GUESSED, BUT POSITION CALCULATED: E5 = D-G!!! -->
  <link name="right_hand_e5">
    <inertial>
      <mass value="0.01"/>
      <origin xyz="0 0 0"/>
      <inertia ixx="0.001" ixy="0.0" ixz="0.0" iyy="0.001" iyz="0.0" izz="0.001"/>
    </inertial>
  </link>
  <!-- THUMB LINKS --><!-- THUMB LINKS --><!-- THUMB LINKS --><!-- THUMB LINKS --><!-- THUMB LINKS --><!-- THUMB LINKS --><!-- THUMB LINKS -->
  <link name="right_hand_z">
    <visual>
      <origin xyz="0 0 0.02442"/>
      <geometry>
        <mesh filename="package://schunk_svh_description/meshes/d10.dae" scale="1 1 1"/>
      </geometry>
      <material name="DarkGrey" />
    </visual>
    <collision>
      <origin xyz="0 0 0.02442"/>
      <geometry>
        <mesh filename="package://schunk_svh_description/meshes/d10.dae" scale="1 1 1"/>
      </geometry>
    </collision>
    <inertial>
      <mass value="0.0739"/>
      <origin xyz="0.0 0.002024 0.178636"/>
      <inertia ixx="0.00103" ixy="-0.0" ixz="-0.0" iyy="0.00165" iyz="4e-05" izz="0.00111"/>
    </inertial>
  </link>
  <link name="right_hand_virtual_a">
    <inertial>
      <mass value="0.01"/>
      <origin xyz="0 0 0"/>
      <inertia ixx="0.001" ixy="0.0" ixz="0.0" iyy="0.001" iyz="0.0" izz="0.001"/>
    </inertial>
  </link>
  <link name="right_hand_a">
    <visual>
      <geometry>
        <mesh filename="package://schunk_svh_description/meshes/d11.dae" scale="1 1 1"/>
      </geometry>
      <material name="DarkGrey" />
    </visual>
    <collision>
      <geometry>
        <mesh filename="package://schunk_svh_description/meshes/d11.dae" scale="1 1 1"/>
      </geometry>
    </collision>
    <inertial>
      <mass value="0.41222"/>
      <origin xyz="0.240205 0.010733 0.00019"/>
      <inertia ixx="0.00413" ixy="0.00073" ixz="-0.0" iyy="0.01679" iyz="0.0" izz="0.01796"/>
    </inertial>
  </link>
  <link name="right_hand_b">
    <visual>
      <geometry>
        <mesh filename="package://schunk_svh_description/meshes/d12.dae" scale="1 1 1"/>
      </geometry>
      <material name="light_grey" />
    </visual>
    <collision>
      <geometry>
        <mesh filename="package://schunk_svh_description/meshes/d12.dae" scale="1 1 1"/>
      </geometry>
    </collision>
    <inertial>
      <mass value="0.08224"/>
      <origin xyz="0.123157 -0.008382 -2.7e-05"/>
      <inertia ixx="0.00089" ixy="5e-05" ixz="0.0" iyy="0.00139" iyz="0.0" izz="0.00103"/>
    </inertial>
  </link>
  <link name="right_hand_c">
    <visual>
      <geometry>
        <mesh filename="package://schunk_svh_description/meshes/d13.dae" scale="1 1 1"/>
      </geometry>
      <material name="DarkGrey" />
    </visual>
    <collision>
      <geometry>
        <mesh filename="package://schunk_svh_description/meshes/d13.dae" scale="1 1 1"/>
      </geometry>
    </collision>
    <inertial>
      <mass value="0.06198"/>
      <origin xyz="0.113729 0.01094 0.0"/>
      <inertia ixx="0.00025" ixy="-0.0" ixz="-0.0" iyy="0.00051" iyz="0.0" izz="0.00052"/>
    </inertial>
  </link>
  <!-- INDEX FINGER LINKS -->  <!-- INDEX FINGER LINKS -->  <!-- INDEX FINGER LINKS -->  <!-- INDEX FINGER LINKS -->  <!-- INDEX FINGER LINKS -->  <!-- INDEX FINGER LINKS -->
  <link name="right_hand_virtual_l">
    <visual>
      <origin xyz="0 0 0.01321"/>
      <geometry>
        <mesh filename="package://schunk_svh_description/meshes/f10.dae"/>
      </geometry>
      <material name="black" />
    </visual>
    <collision>
      <origin xyz="0 0 0.01321"/>
      <geometry>
        <mesh filename="package://schunk_svh_description/meshes/f10.dae"/>
      </geometry>
    </collision>
    <inertial>
      <mass value="0.02383"/>
      <origin xyz="0.003634 0.000206 -0.09885"/>
      <inertia ixx="0.00021" ixy="-0.0" ixz="-1e-05" iyy="0.00011" iyz="-0.0" izz="0.00019"/>
    </inertial>
  </link>
  <link name="right_hand_l">
    <visual>
      <geometry>
        <mesh filename="package://schunk_svh_description/meshes/f11.dae"/>
      </geometry>
      <material name="light_grey" />
    </visual>
    <collision>
      <geometry>
        <mesh filename="package://schunk_svh_description/meshes/f11.dae"/>
      </geometry>
    </collision>
    <inertial>
      <mass value="0.13003"/>
      <origin xyz="0.261673 0.003521 0.0"/>
      <inertia ixx="0.00051" ixy="-3e-05" ixz="0.0" iyy="0.00335" iyz="-0.0" izz="0.00344"/>
    </inertial>
  </link>
  <link name="right_hand_p">
    <visual>
      <geometry>
        <mesh filename="package://schunk_svh_description/meshes/f12.dae"/>
      </geometry>
      <material name="light_grey" />
    </visual>
    <collision>
      <geometry>
        <mesh filename="package://schunk_svh_description/meshes/f12.dae"/>
      </geometry>
    </collision>
    <inertial>
      <mass value="0.03264"/>
      <origin xyz="0.1384 -0.004609 0.0"/>
      <inertia ixx="0.00016" ixy="-0.0" ixz="0.0" iyy="0.00031" iyz="-0.0" izz="0.00024"/>
    </inertial>
  </link>
  <link name="right_hand_t">
    <visual>
      <geometry>
        <mesh filename="package://schunk_svh_description/meshes/f13.dae"/>
      </geometry>
      <material name="DarkGrey" />
    </visual>
    <collision>
      <geometry>
        <mesh filename="package://schunk_svh_description/meshes/f13.dae"/>
      </geometry>
    </collision>
    <inertial>
      <mass value="0.0324"/>
      <origin xyz="0.102924 0.000592 0.0"/>
      <inertia ixx="9e-05" ixy="-1e-05" ixz="-0.0" iyy="0.00017" iyz="0.0" izz="0.00017"/>
    </inertial>
  </link>
  <!-- MIDDLE FINGER LINKS -->  <!-- MIDDLE FINGER LINKS -->  <!-- MIDDLE FINGER LINKS -->  <!-- MIDDLE FINGER LINKS -->  <!-- MIDDLE FINGER LINKS -->  <!-- MIDDLE FINGER LINKS -->
  <link name="right_hand_virtual_k">
    <visual>
      <origin xyz="0 0 0.01321"/>
      <geometry>
        <mesh filename="package://schunk_svh_description/meshes/f20.dae"/>
      </geometry>
      <material name="black" />
    </visual>
    <collision>
      <origin xyz="0 0 0.01321"/>
      <geometry>
        <mesh filename="package://schunk_svh_description/meshes/f20.dae"/>
      </geometry>
    </collision>
    <inertial>
      <mass value="0.02377"/>
      <origin xyz="0.003357 -8e-06 -0.099643"/>
      <inertia ixx="0.00021" ixy="-0.0" ixz="-1e-05" iyy="0.00011" iyz="0.0" izz="0.00019"/>
    </inertial>
  </link>
  <link name="right_hand_k">
    <visual>
      <geometry>
        <mesh filename="package://schunk_svh_description/meshes/f21.dae"/>
      </geometry>
      <material name="light_grey" />
    </visual>
    <collision>
      <geometry>
        <mesh filename="package://schunk_svh_description/meshes/f21.dae"/>
      </geometry>
    </collision>
    <inertial>
      <mass value="0.13474"/>
      <origin xyz="0.271122 0.00413 0.0"/>
      <inertia ixx="0.00052" ixy="-3e-05" ixz="-0.0" iyy="0.0037" iyz="-0.0" izz="0.0038"/>
    </inertial>
  </link>
  <link name="right_hand_o">
    <visual>
      <geometry>
        <mesh filename="package://schunk_svh_description/meshes/f22.dae"/>
      </geometry>
      <material name="light_grey" />
    </visual>
    <collision>
      <geometry>
        <mesh filename="package://schunk_svh_description/meshes/f22.dae"/>
      </geometry>
    </collision>
    <inertial>
      <mass value="0.0422"/>
      <origin xyz="0.16683 -0.003774 0.0"/>
      <inertia ixx="0.0002" ixy="0.0" ixz="-0.0" iyy="0.00047" iyz="0.0" izz="0.0004"/>
    </inertial>
  </link>
  <link name="right_hand_s">
    <visual>
      <geometry>
        <mesh filename="package://schunk_svh_description/meshes/f23.dae"/>
      </geometry>
      <material name="DarkGrey" />
    </visual>
    <collision>
      <geometry>
        <mesh filename="package://schunk_svh_description/meshes/f23.dae"/>
      </geometry>
    </collision>
    <inertial>
      <mass value="0.03239"/>
      <origin xyz="0.102794 0.00042 0.0"/>
      <inertia ixx="9e-05" ixy="-1e-05" ixz="0.0" iyy="0.00017" iyz="0.0" izz="0.00017"/>
    </inertial>
  </link>
  <!-- RING FINGER LINKS -->  <!-- RING FINGER LINKS -->  <!-- RING FINGER LINKS -->  <!-- RING FINGER LINKS -->  <!-- RING FINGER LINKS -->  <!-- RING FINGER LINKS -->
  <link name="right_hand_virtual_j">
    <visual>
      <origin xyz="0 0 -0.01321"/>
      <geometry>
        <mesh filename="package://schunk_svh_description/meshes/f30.dae"/>
      </geometry>
      <material name="black" />
    </visual>
    <collision>
      <origin xyz="0 0 -0.01321"/>
      <geometry>
        <mesh filename="package://schunk_svh_description/meshes/f30.dae"/>
      </geometry>
    </collision>
    <inertial>
      <mass value="0.02377"/>
      <origin xyz="0.003805 0.000386 0.100079"/>
      <inertia ixx="0.00021" ixy="0.0" ixz="1e-05" iyy="0.00011" iyz="-0.0" izz="0.00019"/>
    </inertial>
  </link>
  <link name="right_hand_j">
    <visual>
      <geometry>
        <mesh filename="package://schunk_svh_description/meshes/f31.dae"/>
      </geometry>
      <material name="light_grey" />
    </visual>
    <collision>
      <geometry>
        <mesh filename="package://schunk_svh_description/meshes/f31.dae"/>
      </geometry>
    </collision>
    <inertial>
      <mass value="0.1377"/>
      <origin xyz="0.258283 -0.00154 0.0"/>
      <inertia ixx="0.00055" ixy="0.00018" ixz="-0.0" iyy="0.00411" iyz="0.0" izz="0.00426"/>
    </inertial>
  </link>
  <link name="right_hand_n">
    <visual>
      <geometry>
        <mesh filename="package://schunk_svh_description/meshes/f32.dae"/>
      </geometry>
      <material name="light_grey" />
    </visual>
    <collision>
      <geometry>
        <mesh filename="package://schunk_svh_description/meshes/f32.dae"/>
      </geometry>
    </collision>
    <inertial>
      <mass value="0.04207"/>
      <origin xyz="0.166851 -0.00362 0.0"/>
      <inertia ixx="0.00019" ixy="0.0" ixz="-0.0" iyy="0.00047" iyz="0.0" izz="0.0004"/>
    </inertial>
  </link>
  <link name="right_hand_r">
    <visual>
      <geometry>
        <mesh filename="package://schunk_svh_description/meshes/f33.dae"/>
      </geometry>
      <material name="DarkGrey" />
    </visual>
    <collision>
      <geometry>
        <mesh filename="package://schunk_svh_description/meshes/f33.dae"/>
      </geometry>
    </collision>
    <inertial>
      <mass value="0.03229"/>
      <origin xyz="0.102676 0.000301 0.0"/>
      <inertia ixx="9e-05" ixy="-1e-05" ixz="0.0" iyy="0.00017" iyz="-0.0" izz="0.00017"/>
    </inertial>
  </link>
  <!-- LITTLE FINGER LINKS -->  <!-- LITTLE FINGER LINKS -->  <!-- LITTLE FINGER LINKS -->  <!-- LITTLE FINGER LINKS -->  <!-- LITTLE FINGER LINKS -->  <!-- LITTLE FINGER LINKS -->
  <link name="right_hand_virtual_i">
    <visual>
      <origin xyz="0 0 -0.01321"/>
      <geometry>
        <mesh filename="package://schunk_svh_description/meshes/f40.dae"/>
      </geometry>
      <material name="black" />
    </visual>
    <collision>
      <origin xyz="0 0 -0.01321"/>
      <geometry>
        <mesh filename="package://schunk_svh_description/meshes/f40.dae"/>
      </geometry>
    </collision>
    <inertial>
      <mass value="0.02377"/>
      <origin xyz="0.003653 4.4e-05 0.100085"/>
      <inertia ixx="0.00021" ixy="0.0" ixz="1e-05" iyy="0.00011" iyz="-0.0" izz="0.00019"/>
    </inertial>
  </link>
  <link name="right_hand_i">
    <visual>
      <geometry>
        <mesh filename="package://schunk_svh_description/meshes/f41.dae"/>
      </geometry>
      <material name="light_grey" />
    </visual>
    <collision>
      <geometry>
        <mesh filename="package://schunk_svh_description/meshes/f41.dae"/>
      </geometry>
    </collision>
    <inertial>
      <mass value="0.12544"/>
      <origin xyz="0.232293 0.00622 0.0"/>
      <inertia ixx="0.00049" ixy="6e-05" ixz="-0.0" iyy="0.00316" iyz="0.0" izz="0.00328"/>
    </inertial>
  </link>
  <link name="right_hand_m">
    <visual>
      <geometry>
        <mesh filename="package://schunk_svh_description/meshes/f42.dae"/>
      </geometry>
      <material name="light_grey" />
    </visual>
    <collision>
      <geometry>
        <mesh filename="package://schunk_svh_description/meshes/f42.dae"/>
      </geometry>
    </collision>
    <inertial>
      <mass value="0.02488"/>
      <origin xyz="0.119665 -0.009328 0.0"/>
      <inertia ixx="0.00013" ixy="-0.0" ixz="-0.0" iyy="0.00023" iyz="0.0" izz="0.00016"/>
    </inertial>
  </link>
  <link name="right_hand_q">
    <visual>
      <geometry>
        <mesh filename="package://schunk_svh_description/meshes/f43.dae"/>
      </geometry>
      <material name="DarkGrey" />
    </visual>
    <collision>
      <geometry>
        <mesh filename="package://schunk_svh_description/meshes/f43.dae"/>
      </geometry>
    </collision>
    <inertial>
      <mass value="0.03234"/>
      <origin xyz="0.102896 0.000307 0.0"/>
      <inertia ixx="9e-05" ixy="-1e-05" ixz="-0.0" iyy="0.00017" iyz="0.0" izz="0.00017"/>
    </inertial>
  </link>
  <joint name="right_hand_Thumb_Flexion" type="revolute">
    <parent link="right_hand_virtual_a"/>
    <child link="right_hand_a"/>
    <limit effort="1000.0" lower="0.0" upper="0.9704" velocity="1"/>
    <origin rpy="0 0 -0.9704" xyz="0 0 0"/>
    <axis xyz="0 0 1"/>
  </joint>
  <joint name="right_hand_Thumb_Helper" type="fixed">
    <parent link="right_hand_z"/>
    <child link="right_hand_virtual_a"/>
    <origin rpy="0 -1.5707 3.1416" xyz="0 0 0.04596"/>
  </joint>
  <!-- BASE_LINE JOINTS -->
  <joint name="right_hand_Thumb_Opposition" type="revolute">
    <parent link="right_hand_e1"/>
    <child link="right_hand_z"/>
    <limit effort="1000.0" lower="0.0" upper="0.9879" velocity="1"/>
    <origin rpy="0 0.2618 1.571" xyz="-0.0169 0.02626 0"/>
    <axis xyz="0 0 -1"/>
  </joint>
  <!-- JOINT NOT FOR BASE_LINE. BUT WRITTEN DOWN HERE FOR BETTER UX -->
  <joint name="right_hand_f1" type="fixed">
    <parent link="right_hand_e1"/>
    <child link="right_hand_d"/>
    <origin rpy="0 0 0" xyz="0 0 0"/>
  </joint>
  <joint name="right_hand_f2" type="fixed">
    <parent link="right_hand_d"/>
    <child link="right_hand_h"/>
    <origin rpy="0 0 0" xyz="0 0 0"/>
  </joint>
  <joint name="right_hand_f3" type="fixed">
    <parent link="right_hand_h"/>
    <child link="right_hand_d2"/>
    <origin rpy="0 0 0" xyz="0 0 0"/>
  </joint>
  <joint name="right_hand_f4" type="fixed">
    <parent link="right_hand_base_link"/>
    <child link="right_hand_e1"/>
    <origin rpy="0 0 0" xyz="0 -0.01313 0"/>
  </joint>
  <!-- J5 JOINTS is set to fixed temporarily due to defective DH algo -->
  <joint name="right_hand_j5" type="fixed">
    <parent link="right_hand_e1"/>
    <child link="right_hand_e2"/>
    <!--limit
      effort="1000.0" lower="0.0" upper="0.98786" velocity="1"/-->
    <origin rpy="0 0 0" xyz="0.0184 0.006 0.0375"/>
    <!--axis
      xyz="0 0 ${side*(1)}"/-->
    <!--mimic
      joint="${name}_Thumb_Opposition" multiplier="1" offset="0"/-->
  </joint>
  <joint name="right_hand_f5" type="fixed">
    <parent link="right_hand_e2"/>
    <child link="right_hand_e3"/>
    <origin rpy="0 0 0" xyz="0 -0.0060 0"/>
  </joint>
  <joint name="right_hand_f6" type="fixed">
    <parent link="right_hand_e3"/>
    <child link="right_hand_e"/>
    <origin rpy="0 0 0" xyz="0 0 0"/>
  </joint>
  <joint name="right_hand_f7" type="fixed">
    <parent link="right_hand_e"/>
    <child link="right_hand_e4"/>
    <origin rpy="0 0 0" xyz="0 0 0"/>
  </joint>
  <joint name="right_hand_f8" type="fixed">
    <parent link="right_hand_e"/>
    <child link="right_hand_e5"/>
    <origin rpy="0 0 0" xyz="0 0 0"/>
  </joint>
  <!-- THUMB JOINTS -->
  <joint name="right_hand_j3" type="revolute">
    <parent link="right_hand_a"/>
    <child link="right_hand_b"/>
    <limit effort="1000.0" lower="0.0" upper="0.98506" velocity="1"/>
    <origin rpy="0 0 0" xyz="0.0485 0 0"/>
    <axis xyz="0 0 1"/>
    <mimic joint="right_hand_Thumb_Flexion" multiplier="1.01511" offset="0"/>
  </joint>
  <joint name="right_hand_j4" type="revolute">
    <parent link="right_hand_b"/>
    <child link="right_hand_c"/>
    <limit effort="1000.0" lower="0.0" upper="1.406" velocity="1"/>
    <origin rpy="0 0 0" xyz="0.030 0 0"/>
    <axis xyz="0 0 1"/>
    <mimic joint="right_hand_Thumb_Flexion" multiplier="1.44889" offset="0"/>
  </joint>
  <!-- INDEX FINGER JOINTS -->
  <joint name="right_hand_Index_Finger_Distal" type="revolute">
    <parent link="right_hand_l"/>
    <child link="right_hand_p"/>
    <limit effort="1000.0" lower="0" upper="1.334" velocity="1"/>
    <origin rpy="0 0 0" xyz="0.04804 0 0"/>
    <axis xyz="0 0 1"/>
  </joint>
  <joint name="right_hand_Index_Finger_Proximal" type="revolute">
    <parent link="right_hand_virtual_l"/>
    <child link="right_hand_l"/>
    <limit effort="1000.0" lower="0.0" upper="0.79849" velocity="1"/>
    <origin rpy="-1.5707 0 0" xyz="0 0 0"/>
    <axis xyz="0 0 1"/>
  </joint>
  <!-- JOINT Finger_Spread in BASE_LINE section for better UX -->
  <joint name="right_hand_j14" type="revolute">
    <parent link="right_hand_p"/>
    <child link="right_hand_t"/>
    <limit effort="1000.0" lower="0" upper="1.394" velocity="1"/>
    <origin rpy="0 0 0" xyz="0.026 0 0"/>
    <axis xyz="0 0 1"/>
    <mimic joint="right_hand_Index_Finger_Distal" multiplier="1.0450" offset="0"/>
  </joint>
  <!-- MIDDLE FINGER JOINTS -->
  <joint name="right_hand_Middle_Finger_Proximal" type="revolute">
    <parent link="right_hand_virtual_k"/>
    <child link="right_hand_k"/>
    <limit effort="1000.0" lower="0.0" upper="0.79849" velocity="1"/>
    <origin rpy="-1.5707 0 0" xyz="0 0 0"/>
    <axis xyz="0 0 1"/>
  </joint>
  <joint name="right_hand_Middle_Finger_Distal" type="revolute">
    <parent link="right_hand_k"/>
    <child link="right_hand_o"/>
    <limit effort="1000.0" lower="0" upper="1.334" velocity="1"/>
    <origin rpy="0 0 0" xyz="0.05004 0 0"/>
    <axis xyz="0 0 1"/>
  </joint>
  <joint name="right_hand_j15" type="revolute">
    <parent link="right_hand_o"/>
    <child link="right_hand_s"/>
    <limit effort="1000.0" lower="0" upper="1.334" velocity="1"/>
    <origin rpy="0 0 0" xyz="0.032 0 0"/>
    <axis xyz="0 0 1"/>
    <mimic joint="right_hand_Middle_Finger_Distal" multiplier="1.0454" offset="0"/>
  </joint>
  <!-- RING FINGER JOINTS -->
  <joint name="right_hand_Ring_Finger" type="revolute">
    <parent link="right_hand_virtual_j"/>
    <child link="right_hand_j"/>
    <limit effort="1000.0" lower="0.0" upper="0.98175" velocity="1"/>
    <origin rpy="1.5707 0 0" xyz="0 0 0"/>
    <axis xyz="0 0 1"/>
  </joint>
  <joint name="right_hand_j12" type="revolute">
    <parent link="right_hand_j"/>
    <child link="right_hand_n"/>
    <limit effort="1000.0" lower="0" upper="1.334" velocity="1"/>
    <origin rpy="0 0 0" xyz="0.05004 0 0"/>
    <axis xyz="0 0 1"/>
    <mimic joint="right_hand_Ring_Finger" multiplier="1.3588" offset="0"/>
  </joint>
  <joint name="right_hand_j16" type="revolute">
    <parent link="right_hand_n"/>
    <child link="right_hand_r"/>
    <limit effort="1000.0" lower="0" upper="1.395" velocity="1"/>
    <origin rpy="0 0 0" xyz="0.032 0 0"/>
    <axis xyz="0 0 1"/>
    <mimic joint="right_hand_Ring_Finger" multiplier="1.42093" offset="0"/>
  </joint>
  <!-- PINKY JOINTS -->
  <joint name="right_hand_Pinky" type="revolute">
    <parent link="right_hand_virtual_i"/>
    <child link="right_hand_i"/>
    <limit effort="1000.0" lower="0.0" upper="0.98175" velocity="1"/>
    <origin rpy="1.5707 0 0" xyz="0 0 0"/>
    <axis xyz="0 0 1"/>
  </joint>
  <joint name="right_hand_j13" type="revolute">
    <parent link="right_hand_i"/>
    <child link="right_hand_m"/>
    <limit effort="1000.0" lower="0" upper="1.334" velocity="1"/>
    <origin rpy="0 0 0" xyz="0.04454 0 0"/>
    <axis xyz="0 0 1"/>
    <mimic joint="right_hand_Pinky" multiplier="1.35880" offset="0"/>
  </joint>
  <joint name="right_hand_j17" type="revolute">
    <parent link="right_hand_m"/>
    <child link="right_hand_q"/>
    <limit effort="1000.0" lower="0" upper="1.3971" velocity="1"/>
    <origin rpy="0 0 0" xyz="0.022 0 0"/>
    <axis xyz="0 0 1"/>
    <mimic joint="right_hand_Pinky" multiplier="1.42307" offset="0"/>
  </joint>
  <joint name="right_hand_index_spread" type="revolute">
    <parent link="right_hand_d2"/>
    <child link="right_hand_virtual_l"/>
    <limit effort="1000.0" lower="0.0" upper="0.28833" velocity="1"/>
    <origin rpy="0 -1.5707 1.5707" xyz="-0.025 0 0.110"/>
    <axis xyz="0 0 1"/>
    <mimic joint="right_hand_Finger_Spread" multiplier="0.5" offset="0"/>
  </joint>
  <joint name="right_hand_middle_spread_dummy" type="fixed">
    <parent link="right_hand_d"/>
    <child link="right_hand_virtual_k"/>
    <origin rpy="0 -1.5707 1.5707" xyz="0 0 0.110"/>
  </joint>
  <joint name="right_hand_ring_spread" type="revolute">
    <parent link="right_hand_e5"/>
    <child link="right_hand_virtual_j"/>
    <limit effort="1000.0" lower="0.0" upper="0.28833" velocity="1"/>
    <origin rpy="-1.5707 -1.5707 0" xyz="0.003855 0 0.0655"/>
    <axis xyz="0 0 1"/>
    <mimic joint="right_hand_Finger_Spread" multiplier="0.5" offset="0"/>
  </joint>
  <joint name="right_hand_Finger_Spread" type="revolute">
    <parent link="right_hand_e4"/>
    <child link="right_hand_virtual_i"/>
    <limit effort="1000.0" lower="0.0" upper="0.5829" velocity="1"/>
    <origin rpy="-1.5707 -1.5707 0" xyz="0.025355 0 0.056"/>
    <axis xyz="0 0 1"/>
  </joint>
  <transmission name="right_hand_Thumb_Opposition_trans">
    <type>transmission_interface/SimpleTransmission</type>
    <joint name="right_hand_Thumb_Opposition">
      <!-- <hardwareInterface>hardware_interface/EffortJointInterface</hardwareInterface> -->
      <hardwareInterface>hardware_interface/PositionJointInterface</hardwareInterface>
      <!-- <hardwareInterface>hardware_interface/VelocityJointInterface</hardwareInterface> -->
    </joint>
    <actuator name="right_hand_Thumb_Opposition_motor">
      <mechanicalReduction>1</mechanicalReduction>
      <!-- <hardwareInterface>hardware_interface/EffortJointInterface</hardwareInterface> -->
      <hardwareInterface>hardware_interface/PositionJointInterface</hardwareInterface>
      <!-- <hardwareInterface>hardware_interface/VelocityJointInterface</hardwareInterface> -->
    </actuator>
  </transmission>
  <transmission name="right_hand_Thumb_Flexion_trans">
    <type>transmission_interface/SimpleTransmission</type>
    <joint name="right_hand_Thumb_Flexion">
      <!-- <hardwareInterface>hardware_interface/EffortJointInterface</hardwareInterface> -->
      <hardwareInterface>hardware_interface/PositionJointInterface</hardwareInterface>
      <!-- <hardwareInterface>hardware_interface/VelocityJointInterface</hardwareInterface> -->
    </joint>
    <actuator name="right_hand_Thumb_Flexion_motor">
      <mechanicalReduction>1</mechanicalReduction>
      <!-- <hardwareInterface>hardware_interface/EffortJointInterface</hardwareInterface> -->
      <hardwareInterface>hardware_interface/PositionJointInterface</hardwareInterface>
      <!-- <hardwareInterface>hardware_interface/VelocityJointInterface</hardwareInterface> -->
    </actuator>
  </transmission>
  <transmission name="right_hand_Index_Finger_Proximal_trans">
    <type>transmission_interface/SimpleTransmission</type>
    <joint name="right_hand_Index_Finger_Proximal">
      <!-- <hardwareInterface>hardware_interface/EffortJointInterface</hardwareInterface> -->
      <hardwareInterface>hardware_interface/PositionJointInterface</hardwareInterface>
      <!-- <hardwareInterface>hardware_interface/VelocityJointInterface</hardwareInterface> -->
    </joint>
    <actuator name="right_hand_Index_Finger_Proximal_motor">
      <mechanicalReduction>1</mechanicalReduction>
      <!-- <hardwareInterface>hardware_interface/EffortJointInterface</hardwareInterface> -->
      <hardwareInterface>hardware_interface/PositionJointInterface</hardwareInterface>
      <!-- <hardwareInterface>hardware_interface/VelocityJointInterface</hardwareInterface> -->
    </actuator>
  </transmission>
  <transmission name="right_hand_Index_Finger_Distal_trans">
    <type>transmission_interface/SimpleTransmission</type>
    <joint name="right_hand_Index_Finger_Distal">
      <!-- <hardwareInterface>hardware_interface/EffortJointInterface</hardwareInterface> -->
      <hardwareInterface>hardware_interface/PositionJointInterface</hardwareInterface>
      <!-- <hardwareInterface>hardware_interface/VelocityJointInterface</hardwareInterface> -->
    </joint>
    <actuator name="right_hand_Index_Finger_Distal_motor">
      <mechanicalReduction>1</mechanicalReduction>
      <!-- <hardwareInterface>hardware_interface/EffortJointInterface</hardwareInterface> -->
      <hardwareInterface>hardware_interface/PositionJointInterface</hardwareInterface>
      <!-- <hardwareInterface>hardware_interface/VelocityJointInterface</hardwareInterface> -->
    </actuator>
  </transmission>
  <transmission name="right_hand_Middle_Finger_Proximal_trans">
    <type>transmission_interface/SimpleTransmission</type>
    <joint name="right_hand_Middle_Finger_Proximal">
      <!-- <hardwareInterface>hardware_interface/EffortJointInterface</hardwareInterface> -->
      <hardwareInterface>hardware_interface/PositionJointInterface</hardwareInterface>
      <!-- <hardwareInterface>hardware_interface/VelocityJointInterface</hardwareInterface> -->
    </joint>
    <actuator name="right_hand_Middle_Finger_Proximal_motor">
      <mechanicalReduction>1</mechanicalReduction>
      <!-- <hardwareInterface>hardware_interface/EffortJointInterface</hardwareInterface> -->
      <hardwareInterface>hardware_interface/PositionJointInterface</hardwareInterface>
      <!-- <hardwareInterface>hardware_interface/VelocityJointInterface</hardwareInterface> -->
    </actuator>
  </transmission>
  <transmission name="right_hand_Middle_Finger_Distal_trans">
    <type>transmission_interface/SimpleTransmission</type>
    <joint name="right_hand_Middle_Finger_Distal">
      <!-- <hardwareInterface>hardware_interface/EffortJointInterface</hardwareInterface> -->
      <hardwareInterface>hardware_interface/PositionJointInterface</hardwareInterface>
      <!-- <hardwareInterface>hardware_interface/VelocityJointInterface</hardwareInterface> -->
    </joint>
    <actuator name="right_hand_Middle_Finger_Distal_motor">
      <mechanicalReduction>1</mechanicalReduction>
      <!-- <hardwareInterface>hardware_interface/EffortJointInterface</hardwareInterface> -->
      <hardwareInterface>hardware_interface/PositionJointInterface</hardwareInterface>
      <!-- <hardwareInterface>hardware_interface/VelocityJointInterface</hardwareInterface> -->
    </actuator>
  </transmission>
  <transmission name="right_hand_Finger_Spread_trans">
    <type>transmission_interface/SimpleTransmission</type>
    <joint name="right_hand_Finger_Spread">
      <!-- <hardwareInterface>hardware_interface/EffortJointInterface</hardwareInterface> -->
      <hardwareInterface>hardware_interface/PositionJointInterface</hardwareInterface>
      <!-- <hardwareInterface>hardware_interface/VelocityJointInterface</hardwareInterface> -->
    </joint>
    <actuator name="right_hand_Finger_Spread_motor">
      <mechanicalReduction>1</mechanicalReduction>
      <!-- <hardwareInterface>hardware_interface/EffortJointInterface</hardwareInterface> -->
      <hardwareInterface>hardware_interface/PositionJointInterface</hardwareInterface>
      <!-- <hardwareInterface>hardware_interface/VelocityJointInterface</hardwareInterface> -->
    </actuator>
  </transmission>
  <transmission name="right_hand_Pinky_trans">
    <type>transmission_interface/SimpleTransmission</type>
    <joint name="right_hand_Pinky">
      <!-- <hardwareInterface>hardware_interface/EffortJointInterface</hardwareInterface> -->
      <hardwareInterface>hardware_interface/PositionJointInterface</hardwareInterface>
      <!-- <hardwareInterface>hardware_interface/VelocityJointInterface</hardwareInterface> -->
    </joint>
    <actuator name="right_hand_Pinky_motor">
      <mechanicalReduction>1</mechanicalReduction>
      <!-- <hardwareInterface>hardware_interface/EffortJointInterface</hardwareInterface> -->
      <hardwareInterface>hardware_interface/PositionJointInterface</hardwareInterface>
      <!-- <hardwareInterface>hardware_interface/VelocityJointInterface</hardwareInterface> -->
    </actuator>
  </transmission>
  <transmission name="right_hand_Ring_Finger_trans">
    <type>transmission_interface/SimpleTransmission</type>
    <joint name="right_hand_Ring_Finger">
      <!-- <hardwareInterface>hardware_interface/EffortJointInterface</hardwareInterface> -->
      <hardwareInterface>hardware_interface/PositionJointInterface</hardwareInterface>
      <!-- <hardwareInterface>hardware_interface/VelocityJointInterface</hardwareInterface> -->
    </joint>
    <actuator name="right_hand_Ring_Finger_motor">
      <mechanicalReduction>1</mechanicalReduction>
      <!-- <hardwareInterface>hardware_interface/EffortJointInterface</hardwareInterface> -->
      <hardwareInterface>hardware_interface/PositionJointInterface</hardwareInterface>
      <!-- <hardwareInterface>hardware_interface/VelocityJointInterface</hardwareInterface> -->
    </actuator>
  </transmission>
  <gazebo>
    <plugin filename="libgazebo_ros_control.so" name="gazebo_ros_control">
      <legacyModeNS>false</legacyModeNS>
      <robotNamespace>/</robotNamespace>
      <robotSimType>gazebo_ros_control/DefaultRobotHWSim</robotSimType>
    </plugin>
  </gazebo>
  <gazebo>
    <plugin filename="libroboticsgroup_upatras_gazebo_mimic_joint_plugin.so" name="right_hand_j3_mimic_joint_plugin">
      <joint>right_hand_Thumb_Flexion</joint>
      <mimicJoint>right_hand_j3</mimicJoint>
      <!-- if set to true, PID parameters from "/gazebo_ros_control/pid_gains/${mimic_joint}" are loaded -->
      <hasPID/>
      <multiplier>1.01511</multiplier>
      <offset>0</offset>
      <sensitiveness>0.0</sensitiveness>
      <!-- if absolute difference between setpoint and process value is below this threshold, do nothing; 0.0 = disable [rad] -->
      <maxEffort>100.0</maxEffort>
      <robotNamespace>/</robotNamespace>
    </plugin>
  </gazebo>
  <gazebo>
    <plugin filename="libroboticsgroup_upatras_gazebo_mimic_joint_plugin.so" name="right_hand_j4_mimic_joint_plugin">
      <joint>right_hand_Thumb_Flexion</joint>
      <mimicJoint>right_hand_j4</mimicJoint>
      <!-- if set to true, PID parameters from "/gazebo_ros_control/pid_gains/${mimic_joint}" are loaded -->
      <hasPID/>
      <multiplier>1.44889</multiplier>
      <offset>0</offset>
      <sensitiveness>0.0</sensitiveness>
      <!-- if absolute difference between setpoint and process value is below this threshold, do nothing; 0.0 = disable [rad] -->
      <maxEffort>100.0</maxEffort>
      <robotNamespace>/</robotNamespace>
    </plugin>
  </gazebo>
  <gazebo>
    <plugin filename="libroboticsgroup_upatras_gazebo_mimic_joint_plugin.so" name="right_hand_j14_mimic_joint_plugin">
      <joint>right_hand_Index_Finger_Distal</joint>
      <mimicJoint>right_hand_j14</mimicJoint>
      <!-- if set to true, PID parameters from "/gazebo_ros_control/pid_gains/${mimic_joint}" are loaded -->
      <hasPID/>
      <multiplier>1.045</multiplier>
      <offset>0</offset>
      <sensitiveness>0.0</sensitiveness>
      <!-- if absolute difference between setpoint and process value is below this threshold, do nothing; 0.0 = disable [rad] -->
      <maxEffort>100.0</maxEffort>
      <robotNamespace>/</robotNamespace>
    </plugin>
  </gazebo>
  <gazebo>
    <plugin filename="libroboticsgroup_upatras_gazebo_mimic_joint_plugin.so" name="right_hand_j15_mimic_joint_plugin">
      <joint>right_hand_Middle_Finger_Distal</joint>
      <mimicJoint>right_hand_j15</mimicJoint>
      <!-- if set to true, PID parameters from "/gazebo_ros_control/pid_gains/${mimic_joint}" are loaded -->
      <hasPID/>
      <multiplier>1.0454</multiplier>
      <offset>0</offset>
      <sensitiveness>0.0</sensitiveness>
      <!-- if absolute difference between setpoint and process value is below this threshold, do nothing; 0.0 = disable [rad] -->
      <maxEffort>100.0</maxEffort>
      <robotNamespace>/</robotNamespace>
    </plugin>
  </gazebo>
  <gazebo>
    <plugin filename="libroboticsgroup_upatras_gazebo_mimic_joint_plugin.so" name="right_hand_j12_mimic_joint_plugin">
      <joint>right_hand_Ring_Finger</joint>
      <mimicJoint>right_hand_j12</mimicJoint>
      <!-- if set to true, PID parameters from "/gazebo_ros_control/pid_gains/${mimic_joint}" are loaded -->
      <hasPID/>
      <multiplier>1.3588</multiplier>
      <offset>0</offset>
      <sensitiveness>0.0</sensitiveness>
      <!-- if absolute difference between setpoint and process value is below this threshold, do nothing; 0.0 = disable [rad] -->
      <maxEffort>100.0</maxEffort>
      <robotNamespace>/</robotNamespace>
    </plugin>
  </gazebo>
  <gazebo>
    <plugin filename="libroboticsgroup_upatras_gazebo_mimic_joint_plugin.so" name="right_hand_j16_mimic_joint_plugin">
      <joint>right_hand_Ring_Finger</joint>
      <mimicJoint>right_hand_j16</mimicJoint>
      <!-- if set to true, PID parameters from "/gazebo_ros_control/pid_gains/${mimic_joint}" are loaded -->
      <hasPID/>
      <multiplier>1.42093</multiplier>
      <offset>0</offset>
      <sensitiveness>0.0</sensitiveness>
      <!-- if absolute difference between setpoint and process value is below this threshold, do nothing; 0.0 = disable [rad] -->
      <maxEffort>100.0</maxEffort>
      <robotNamespace>/</robotNamespace>
    </plugin>
  </gazebo>
  <gazebo>
    <plugin filename="libroboticsgroup_upatras_gazebo_mimic_joint_plugin.so" name="right_hand_j13_mimic_joint_plugin">
      <joint>right_hand_Pinky</joint>
      <mimicJoint>right_hand_j13</mimicJoint>
      <!-- if set to true, PID parameters from "/gazebo_ros_control/pid_gains/${mimic_joint}" are loaded -->
      <hasPID/>
      <multiplier>1.3588</multiplier>
      <offset>0</offset>
      <sensitiveness>0.0</sensitiveness>
      <!-- if absolute difference between setpoint and process value is below this threshold, do nothing; 0.0 = disable [rad] -->
      <maxEffort>100.0</maxEffort>
      <robotNamespace>/</robotNamespace>
    </plugin>
  </gazebo>
  <gazebo>
    <plugin filename="libroboticsgroup_upatras_gazebo_mimic_joint_plugin.so" name="right_hand_j17_mimic_joint_plugin">
      <joint>right_hand_Pinky</joint>
      <mimicJoint>right_hand_j17</mimicJoint>
      <!-- if set to true, PID parameters from "/gazebo_ros_control/pid_gains/${mimic_joint}" are loaded -->
      <hasPID/>
      <multiplier>1.42307</multiplier>
      <offset>0</offset>
      <sensitiveness>0.0</sensitiveness>
      <!-- if absolute difference between setpoint and process value is below this threshold, do nothing; 0.0 = disable [rad] -->
      <maxEffort>100.0</maxEffort>
      <robotNamespace>/</robotNamespace>
    </plugin>
  </gazebo>
  <gazebo>
    <plugin filename="libroboticsgroup_upatras_gazebo_mimic_joint_plugin.so" name="right_hand_index_spread_mimic_joint_plugin">
      <joint>right_hand_Finger_Spread</joint>
      <mimicJoint>right_hand_index_spread</mimicJoint>
      <!-- if set to true, PID parameters from "/gazebo_ros_control/pid_gains/${mimic_joint}" are loaded -->
      <hasPID/>
      <multiplier>0.5</multiplier>
      <offset>0</offset>
      <sensitiveness>0.0</sensitiveness>
      <!-- if absolute difference between setpoint and process value is below this threshold, do nothing; 0.0 = disable [rad] -->
      <maxEffort>100.0</maxEffort>
      <robotNamespace>/</robotNamespace>
    </plugin>
  </gazebo>
  <gazebo>
    <plugin filename="libroboticsgroup_upatras_gazebo_mimic_joint_plugin.so" name="right_hand_ring_spread_mimic_joint_plugin">
      <joint>right_hand_Finger_Spread</joint>
      <mimicJoint>right_hand_ring_spread</mimicJoint>
      <!-- if set to true, PID parameters from "/gazebo_ros_control/pid_gains/${mimic_joint}" are loaded -->
      <hasPID/>
      <multiplier>0.5</multiplier>
      <offset>0</offset>
      <sensitiveness>0.0</sensitiveness>
      <!-- if absolute difference between setpoint and process value is below this threshold, do nothing; 0.0 = disable [rad] -->
      <maxEffort>100.0</maxEffort>
      <robotNamespace>/</robotNamespace>
    </plugin>
  </gazebo>
  
  
  <!-- ################################### -->
  <!-- ### End Schunk right hand      #### -->
  <!-- ################################### -->

  <!-- ################################### -->
  <!-- ### Schunk left hand           #### -->
  <!-- ################################### -->


  <!-- <joint name="l_robotiq_hand_joint" type="fixed">
    <origin rpy="1.57 0 1.0" xyz="0 0 0.05398" />
    <parent link="l_robotiq_fts300_fts_toolside" />
    <child link="left_schunk_base_link" />
  </joint> -->


  <!-- <joint name="l_robotiq_hand_joint" type="fixed">
    <origin rpy="1.57 0 1.0" xyz="0 0 0.05398" />
    <parent link="l_robotiq_fts300_fts_toolside" />
    <child link="left_schunk_base_link" />
  </joint> -->

  <joint name="l_robotiq_hand_joint" type="fixed">
    <origin rpy="0.0 0 1.0" xyz="0 0 0.0001" />
    <parent link="l_robotiq_fts300_fts_toolside" />
    <child link="left_schunk_base_link" />
  </joint>

  <link name="left_schunk_base_link">
    <inertial>
      <origin xyz="0 0 0" rpy="0 0 0"/>
      <mass value="0.00001"/> <!-- Small non-zero mass -->
      <inertia ixx="0.00000001" ixy="0.0" ixz="0.0" iyy="0.00000001" iyz="0.0" izz="0.00000001"/> <!-- Small non-zero inertia values -->
    </inertial>
  </link>  
  
  
  
  <!-- RIGHT HAND = 1, LEFT HAND = -1 -->
  <!-- BASE_LINE LINKS -->
  <joint name="left_hand_base_joint" type="fixed">
    <origin rpy="0 0 0" xyz="0 0 0" />
    <parent link="left_schunk_base_link" />
    <child link="left_hand_base_link" />
  </joint>
  <link name="left_hand_base_link">
    <origin rpy="0 0 0" xyz="0 0 0" />
    <visual>
      <origin rpy="0 0 0" xyz="0 0 0" />
      <geometry>
        <mesh filename="package://schunk_svh_description/meshes/base10.dae" />
      </geometry>
      <material name="light_grey"/>
    </visual>
    <collision>
      <origin rpy="0 0 0" xyz="0 0 0" />
      <geometry>
        <mesh filename="package://schunk_svh_description/meshes/base10.dae" />
      </geometry>
    </collision>
    <inertial>
      <mass value="0.57743" />
      <origin xyz="0.0 -2.3e-05 0.139371" />
      <inertia ixx="0.04725" ixy="-0.0" ixz="-0.0" iyy="0.04717" iyz="0.0" izz="0.07606" />
    </inertial>
  </link>
  <link name="left_hand_d">
    <inertial>
      <mass value="0.01" />
      <origin xyz="0 0 0" />
      <inertia ixx="0.001" ixy="0.0" ixz="0.0" iyy="0.001" iyz="0.0" izz="0.001" />
    </inertial>
  </link>
  <link name="left_hand_h">
    <inertial>
      <mass value="0.01" />
      <origin xyz="0 0 0" />
      <inertia ixx="0.001" ixy="0.0" ixz="0.0" iyy="0.001" iyz="0.0" izz="0.001" />
    </inertial>
  </link>
  <link name="left_hand_d2">
    <inertial>
      <mass value="0.01" />
      <origin xyz="0 0 0" />
      <inertia ixx="0.001" ixy="0.0" ixz="0.0" iyy="0.001" iyz="0.0" izz="0.001" />
    </inertial>
  </link>
  <!-- LENGTH NOT FOUND IN DATASHEET! GUESSED!!! -->
  <link name="left_hand_e1">
    <visual>
      <origin rpy="0 0 0" xyz="0 0.01313 0" />
      <geometry>
        <mesh filename="package://schunk_svh_description/meshes/h10.dae" scale="-1 1 1" />
      </geometry>
      <material name="DarkGrey" />
    </visual>
    <collision>
      <origin rpy="0 0 0" xyz="0 0.01313 0" />
      <geometry>
        <mesh filename="package://schunk_svh_description/meshes/h10.dae" scale="-1 1 1" />
      </geometry>
    </collision>
    <inertial>
      <mass value="0.01" />
      <origin xyz="0 0 0" />
      <inertia ixx="0.001" ixy="0.0" ixz="0.0" iyy="0.001" iyz="0.0" izz="0.001" />
    </inertial>
  </link>
  <!-- LENGTH NOT FOUND IN DATASHEET! GUESSED!!! -->
  <link name="left_hand_e2">
    <visual>
      <origin xyz="0.0007 0 -0.01002" />
      <geometry>
        <mesh filename="package://schunk_svh_description/meshes/h11.dae" scale="-1 1 1" />
      </geometry>
      <material name="DarkGrey" />
    </visual>
    <collision>
      <origin xyz="0.0007 0 -0.01002" />
      <geometry>
        <mesh filename="package://schunk_svh_description/meshes/h11.dae" scale="-1 1 1" />
      </geometry>
    </collision>
    <inertial>
      <mass value="0.46184" />
      <origin xyz="0.145071 -0.037868 0.323449" />
      <inertia ixx="0.01908" ixy="-0.00121" ixz="-0.00011" iyy="0.01704" iyz="0.00277" izz="0.00862" />
    </inertial>
  </link>
  <!-- LENGTH NOT FOUND IN DATASHEET! GUESSED!!! -->
  <link name="left_hand_e3">
    <inertial>
      <mass value="0.01" />
      <origin xyz="0 0 0" />
      <inertia ixx="0.001" ixy="0.0" ixz="0.0" iyy="0.001" iyz="0.0" izz="0.001" />
    </inertial>
  </link>
  <link name="left_hand_e">
    <inertial>
      <origin xyz="0 0 0" rpy="0 0 0"/>
      <mass value="0.00001"/> <!-- Small non-zero mass -->
      <inertia ixx="0.00000001" ixy="0.0" ixz="0.0" iyy="0.00000001" iyz="0.0" izz="0.00000001"/> <!-- Small non-zero inertia values -->
    </inertial>  
  </link>
  <!-- LENGTH NOT FOUND IN DATASHEET! GUESSED, BUT POSITION CALCULATED: E4 = D-G-F!!! -->
  <link name="left_hand_e4">
    <inertial>
      <mass value="0.01" />
      <origin xyz="0 0 0" />
      <inertia ixx="0.001" ixy="0.0" ixz="0.0" iyy="0.001" iyz="0.0" izz="0.001" />
    </inertial>
  </link>
  <!-- LENGTH NOT FOUND IN DATASHEET! GUESSED, BUT POSITION CALCULATED: E5 = D-G!!! -->
  <link name="left_hand_e5">
    <inertial>
      <mass value="0.01" />
      <origin xyz="0 0 0" />
      <inertia ixx="0.001" ixy="0.0" ixz="0.0" iyy="0.001" iyz="0.0" izz="0.001" />
    </inertial>
  </link>
  <!-- THUMB LINKS -->
  <link name="left_hand_z">
    <visual>
      <origin xyz="0 0 0.02442" />
      <geometry>
        <mesh filename="package://schunk_svh_description/meshes/d10.dae" scale="1 -1 1" />
      </geometry>
      <material name="DarkGrey" />
    </visual>
    <collision>
      <origin xyz="0 0 0.02442" />
      <geometry>
        <mesh filename="package://schunk_svh_description/meshes/d10.dae" scale="1 -1 1" />
      </geometry>
    </collision>
    <inertial>
      <mass value="0.0739" />
      <origin xyz="0.0 0.002024 0.178636" />
      <inertia ixx="0.00103" ixy="-0.0" ixz="-0.0" iyy="0.00165" iyz="4e-05" izz="0.00111" />
    </inertial>
  </link>
  <link name="left_hand_virtual_a">
    <inertial>
      <mass value="0.01" />
      <origin xyz="0 0 0" />
      <inertia ixx="0.001" ixy="0.0" ixz="0.0" iyy="0.001" iyz="0.0" izz="0.001" />
    </inertial>
  </link>
  <link name="left_hand_a">
    <visual>
      <geometry>
        <mesh filename="package://schunk_svh_description/meshes/d11.dae" scale="1 -1 -1" />
      </geometry>
      <material name="DarkGrey" />
    </visual>
    <collision>
      <geometry>
        <mesh filename="package://schunk_svh_description/meshes/d11.dae" scale="1 -1 -1" />
      </geometry>
    </collision>
    <inertial>
      <mass value="0.41222" />
      <origin xyz="0.240205 0.010733 0.00019" />
      <inertia ixx="0.00413" ixy="0.00073" ixz="-0.0" iyy="0.01679" iyz="0.0" izz="0.01796" />
    </inertial>
  </link>
  <link name="left_hand_b">
    <visual>
      <geometry>
        <mesh filename="package://schunk_svh_description/meshes/d12.dae" scale="1 -1 -1" />
      </geometry>
      <material name="light_grey" />
    </visual>
    <collision>
      <geometry>
        <mesh filename="package://schunk_svh_description/meshes/d12.dae" scale="1 -1 -1" />
      </geometry>
    </collision>
    <inertial>
      <mass value="0.08224" />
      <origin xyz="0.123157 -0.008382 -2.7e-05" />
      <inertia ixx="0.00089" ixy="5e-05" ixz="0.0" iyy="0.00139" iyz="0.0" izz="0.00103" />
    </inertial>
  </link>
  <link name="left_hand_c">
    <visual>
      <geometry>
        <mesh filename="package://schunk_svh_description/meshes/d13.dae" scale="1 -1 -1" />
      </geometry>
      <material name="DarkGrey" />
    </visual>
    <collision>
      <geometry>
        <mesh filename="package://schunk_svh_description/meshes/d13.dae" scale="1 -1 -1" />
      </geometry>
    </collision>
    <inertial>
      <mass value="0.06198" />
      <origin xyz="0.113729 0.01094 0.0" />
      <inertia ixx="0.00025" ixy="-0.0" ixz="-0.0" iyy="0.00051" iyz="0.0" izz="0.00052" />
    </inertial>
  </link>
  <!-- INDEX FINGER LINKS -->
  <link name="left_hand_virtual_l">
    <visual>
      <origin xyz="0 0 0.01321" />
      <geometry>
        <mesh filename="package://schunk_svh_description/meshes/f10.dae" />
      </geometry>
      <material name="black" />
    </visual>
    <collision>
      <origin xyz="0 0 0.01321" />
      <geometry>
        <mesh filename="package://schunk_svh_description/meshes/f10.dae" />
      </geometry>
    </collision>
    <inertial>
      <mass value="0.02383" />
      <origin xyz="0.003634 0.000206 -0.09885" />
      <inertia ixx="0.00021" ixy="-0.0" ixz="-1e-05" iyy="0.00011" iyz="-0.0" izz="0.00019" />
    </inertial>
  </link>
  <link name="left_hand_l">
    <visual>
      <geometry>
        <mesh filename="package://schunk_svh_description/meshes/f11.dae" />
      </geometry>
      <material name="light_grey" />
    </visual>
    <collision>
      <geometry>
        <mesh filename="package://schunk_svh_description/meshes/f11.dae" />
      </geometry>
    </collision>
    <inertial>
      <mass value="0.13003" />
      <origin xyz="0.261673 0.003521 0.0" />
      <inertia ixx="0.00051" ixy="-3e-05" ixz="0.0" iyy="0.00335" iyz="-0.0" izz="0.00344" />
    </inertial>
  </link>
  <link name="left_hand_p">
    <visual>
      <geometry>
        <mesh filename="package://schunk_svh_description/meshes/f12.dae" />
      </geometry>
      <material name="light_grey" />
    </visual>
    <collision>
      <geometry>
        <mesh filename="package://schunk_svh_description/meshes/f12.dae" />
      </geometry>
    </collision>
    <inertial>
      <mass value="0.03264" />
      <origin xyz="0.1384 -0.004609 0.0" />
      <inertia ixx="0.00016" ixy="-0.0" ixz="0.0" iyy="0.00031" iyz="-0.0" izz="0.00024" />
    </inertial>
  </link>
  <link name="left_hand_t">
    <visual>
      <geometry>
        <mesh filename="package://schunk_svh_description/meshes/f13.dae" />
      </geometry>
      <material name="DarkGrey" />
    </visual>
    <collision>
      <geometry>
        <mesh filename="package://schunk_svh_description/meshes/f13.dae" />
      </geometry>
    </collision>
    <inertial>
      <mass value="0.0324" />
      <origin xyz="0.102924 0.000592 0.0" />
      <inertia ixx="9e-05" ixy="-1e-05" ixz="-0.0" iyy="0.00017" iyz="0.0" izz="0.00017" />
    </inertial>
  </link>
  <!-- MIDDLE FINGER LINKS -->
  <link name="left_hand_virtual_k">
    <visual>
      <origin xyz="0 0 0.01321" />
      <geometry>
        <mesh filename="package://schunk_svh_description/meshes/f20.dae" />
      </geometry>
      <material name="black" />
    </visual>
    <collision>
      <origin xyz="0 0 0.01321" />
      <geometry>
        <mesh filename="package://schunk_svh_description/meshes/f20.dae" />
      </geometry>
    </collision>
    <inertial>
      <mass value="0.02377" />
      <origin xyz="0.003357 -8e-06 -0.099643" />
      <inertia ixx="0.00021" ixy="-0.0" ixz="-1e-05" iyy="0.00011" iyz="0.0" izz="0.00019" />
    </inertial>
  </link>
  <link name="left_hand_k">
    <visual>
      <geometry>
        <mesh filename="package://schunk_svh_description/meshes/f21.dae" />
      </geometry>
      <material name="light_grey" />
    </visual>
    <collision>
      <geometry>
        <mesh filename="package://schunk_svh_description/meshes/f21.dae" />
      </geometry>
    </collision>
    <inertial>
      <mass value="0.13474" />
      <origin xyz="0.271122 0.00413 0.0" />
      <inertia ixx="0.00052" ixy="-3e-05" ixz="-0.0" iyy="0.0037" iyz="-0.0" izz="0.0038" />
    </inertial>
  </link>
  <link name="left_hand_o">
    <visual>
      <geometry>
        <mesh filename="package://schunk_svh_description/meshes/f22.dae" />
      </geometry>
      <material name="light_grey" />
    </visual>
    <collision>
      <geometry>
        <mesh filename="package://schunk_svh_description/meshes/f22.dae" />
      </geometry>
    </collision>
    <inertial>
      <mass value="0.0422" />
      <origin xyz="0.16683 -0.003774 0.0" />
      <inertia ixx="0.0002" ixy="0.0" ixz="-0.0" iyy="0.00047" iyz="0.0" izz="0.0004" />
    </inertial>
  </link>
  <link name="left_hand_s">
    <visual>
      <geometry>
        <mesh filename="package://schunk_svh_description/meshes/f23.dae" />
      </geometry>
      <material name="DarkGrey" />
    </visual>
    <collision>
      <geometry>
        <mesh filename="package://schunk_svh_description/meshes/f23.dae" />
      </geometry>
    </collision>
    <inertial>
      <mass value="0.03239" />
      <origin xyz="0.102794 0.00042 0.0" />
      <inertia ixx="9e-05" ixy="-1e-05" ixz="0.0" iyy="0.00017" iyz="0.0" izz="0.00017" />
    </inertial>
  </link>
  <!-- RING FINGER LINKS -->
  <link name="left_hand_virtual_j">
    <visual>
      <origin xyz="0 0 -0.01321" />
      <geometry>
        <mesh filename="package://schunk_svh_description/meshes/f30.dae" />
      </geometry>
      <material name="black" />
    </visual>
    <collision>
      <origin xyz="0 0 -0.01321" />
      <geometry>
        <mesh filename="package://schunk_svh_description/meshes/f30.dae" />
      </geometry>
    </collision>
    <inertial>
      <mass value="0.02377" />
      <origin xyz="0.003805 0.000386 0.100079" />
      <inertia ixx="0.00021" ixy="0.0" ixz="1e-05" iyy="0.00011" iyz="-0.0" izz="0.00019" />
    </inertial>
  </link>
  <link name="left_hand_j">
    <visual>
      <geometry>
        <mesh filename="package://schunk_svh_description/meshes/f31.dae" />
      </geometry>
      <material name="light_grey" />
    </visual>
    <collision>
      <geometry>
        <mesh filename="package://schunk_svh_description/meshes/f31.dae" />
      </geometry>
    </collision>
    <inertial>
      <mass value="0.1377" />
      <origin xyz="0.258283 -0.00154 0.0" />
      <inertia ixx="0.00055" ixy="0.00018" ixz="-0.0" iyy="0.00411" iyz="0.0" izz="0.00426" />
    </inertial>
  </link>
  <link name="left_hand_n">
    <visual>
      <geometry>
        <mesh filename="package://schunk_svh_description/meshes/f32.dae" />
      </geometry>
      <material name="light_grey" />
    </visual>
    <collision>
      <geometry>
        <mesh filename="package://schunk_svh_description/meshes/f32.dae" />
      </geometry>
    </collision>
    <inertial>
      <mass value="0.04207" />
      <origin xyz="0.166851 -0.00362 0.0" />
      <inertia ixx="0.00019" ixy="0.0" ixz="-0.0" iyy="0.00047" iyz="0.0" izz="0.0004" />
    </inertial>
  </link>
  <link name="left_hand_r">
    <visual>
      <geometry>
        <mesh filename="package://schunk_svh_description/meshes/f33.dae" />
      </geometry>
      <material name="DarkGrey" />
    </visual>
    <collision>
      <geometry>
        <mesh filename="package://schunk_svh_description/meshes/f33.dae" />
      </geometry>
    </collision>
    <inertial>
      <mass value="0.03229" />
      <origin xyz="0.102676 0.000301 0.0" />
      <inertia ixx="9e-05" ixy="-1e-05" ixz="0.0" iyy="0.00017" iyz="-0.0" izz="0.00017" />
    </inertial>
  </link>
  <!-- LITTLE FINGER LINKS -->
  <link name="left_hand_virtual_i">
    <visual>
      <origin xyz="0 0 -0.01321" />
      <geometry>
        <mesh filename="package://schunk_svh_description/meshes/f40.dae" />
      </geometry>
      <material name="black" />
    </visual>
    <collision>
      <origin xyz="0 0 -0.01321" />
      <geometry>
        <mesh filename="package://schunk_svh_description/meshes/f40.dae" />
      </geometry>
    </collision>
    <inertial>
      <mass value="0.02377" />
      <origin xyz="0.003653 4.4e-05 0.100085" />
      <inertia ixx="0.00021" ixy="0.0" ixz="1e-05" iyy="0.00011" iyz="-0.0" izz="0.00019" />
    </inertial>
  </link>
  <link name="left_hand_i">
    <visual>
      <geometry>
        <mesh filename="package://schunk_svh_description/meshes/f41.dae" />
      </geometry>
      <material name="light_grey" />
    </visual>
    <collision>
      <geometry>
        <mesh filename="package://schunk_svh_description/meshes/f41.dae" />
      </geometry>
    </collision>
    <inertial>
      <mass value="0.12544" />
      <origin xyz="0.232293 0.00622 0.0" />
      <inertia ixx="0.00049" ixy="6e-05" ixz="-0.0" iyy="0.00316" iyz="0.0" izz="0.00328" />
    </inertial>
  </link>
  <link name="left_hand_m">
    <visual>
      <geometry>
        <mesh filename="package://schunk_svh_description/meshes/f42.dae" />
      </geometry>
      <material name="light_grey" />
    </visual>
    <collision>
      <geometry>
        <mesh filename="package://schunk_svh_description/meshes/f42.dae" />
      </geometry>
    </collision>
    <inertial>
      <mass value="0.02488" />
      <origin xyz="0.119665 -0.009328 0.0" />
      <inertia ixx="0.00013" ixy="-0.0" ixz="-0.0" iyy="0.00023" iyz="0.0" izz="0.00016" />
    </inertial>
  </link>
  <link name="left_hand_q">
    <visual>
      <geometry>
        <mesh filename="package://schunk_svh_description/meshes/f43.dae" />
      </geometry>
      <material name="DarkGrey" />
    </visual>
    <collision>
      <geometry>
        <mesh filename="package://schunk_svh_description/meshes/f43.dae" />
      </geometry>
    </collision>
    <inertial>
      <mass value="0.03234" />
      <origin xyz="0.102896 0.000307 0.0" />
      <inertia ixx="9e-05" ixy="-1e-05" ixz="-0.0" iyy="0.00017" iyz="0.0" izz="0.00017" />
    </inertial>
  </link>
  <joint name="left_hand_Thumb_Flexion" type="revolute">
    <parent link="left_hand_virtual_a" />
    <child link="left_hand_a" />
    <limit effort="1000.0" lower="0.0" upper="0.9704" velocity="1" />
    <origin rpy="0 0 0.9704" xyz="0 0 0" />
    <axis xyz="0 0 -1" />
  </joint>
  <joint name="left_hand_Thumb_Helper" type="fixed">
    <parent link="left_hand_z" />
    <child link="left_hand_virtual_a" />
    <origin rpy="0 -1.5707 3.1416" xyz="0 0 0.04596" />
  </joint>
  <!-- BASE_LINE JOINTS -->
  <joint name="left_hand_Thumb_Opposition" type="revolute">
    <parent link="left_hand_e1" />
    <child link="left_hand_z" />
    <limit effort="1000.0" lower="0.0" upper="0.9879" velocity="1" />
    <origin rpy="0 0.2618 1.571" xyz="0.0169 0.02626 0" />
    <axis xyz="0 0 1" />
  </joint>
  <!-- JOINT NOT FOR BASE_LINE. BUT WRITTEN DOWN HERE FOR BETTER UX -->
  <joint name="left_hand_f1" type="fixed">
    <parent link="left_hand_e1" />
    <child link="left_hand_d" />
    <origin rpy="0 0 0" xyz="0 0 0" />
  </joint>
  <joint name="left_hand_f2" type="fixed">
    <parent link="left_hand_d" />
    <child link="left_hand_h" />
    <origin rpy="0 0 0" xyz="0 0 0" />
  </joint>
  <joint name="left_hand_f3" type="fixed">
    <parent link="left_hand_h" />
    <child link="left_hand_d2" />
    <origin rpy="0 0 0" xyz="0 0 0" />
  </joint>
  <joint name="left_hand_f4" type="fixed">
    <parent link="left_hand_base_link" />
    <child link="left_hand_e1" />
    <origin rpy="0 0 0" xyz="0 -0.01313 0" />
  </joint>
  <!-- J5 JOINTS is set to fixed temporarily due to defective DH algo -->
  <joint name="left_hand_j5" type="fixed">
    <parent link="left_hand_e1" />
    <child link="left_hand_e2" />
    <!--limit
    effort="1000.0" lower="0.0" upper="0.98786" velocity="1"/-->
    <origin rpy="0 0 0" xyz="-0.0184 0.006 0.0375" />
    <!--axis
    xyz="0 0 ${side*(1)}"/-->
    <!--mimic
    joint="${name}_Thumb_Opposition" multiplier="1" offset="0"/-->
  </joint>
  <joint name="left_hand_f5" type="fixed">
    <parent link="left_hand_e2" />
    <child link="left_hand_e3" />
    <origin rpy="0 0 0" xyz="0 -0.0060 0" />
  </joint>
  <joint name="left_hand_f6" type="fixed">
    <parent link="left_hand_e3" />
    <child link="left_hand_e" />
    <origin rpy="0 0 0" xyz="0 0 0" />
  </joint>
  <joint name="left_hand_f7" type="fixed">
    <parent link="left_hand_e" />
    <child link="left_hand_e4" />
    <origin rpy="0 0 0" xyz="0 0 0" />
  </joint>
  <joint name="left_hand_f8" type="fixed">
    <parent link="left_hand_e" />
    <child link="left_hand_e5" />
    <origin rpy="0 0 0" xyz="0 0 0" />
  </joint>
  <!-- THUMB JOINTS -->
  <joint name="left_hand_j3" type="revolute">
    <parent link="left_hand_a" />
    <child link="left_hand_b" />
    <limit effort="1000.0" lower="0.0" upper="0.98506" velocity="1" />
    <origin rpy="0 0 0" xyz="0.0485 0 0" />
    <axis xyz="0 0 -1" />
    <mimic joint="left_hand_Thumb_Flexion" multiplier="1.01511" offset="0" />
  </joint>
  <joint name="left_hand_j4" type="revolute">
    <parent link="left_hand_b" />
    <child link="left_hand_c" />
    <limit effort="1000.0" lower="0.0" upper="1.406" velocity="1" />
    <origin rpy="0 0 0" xyz="0.030 0 0" />
    <axis xyz="0 0 -1" />
    <mimic joint="left_hand_Thumb_Flexion" multiplier="1.44889" offset="0" />
  </joint>
  <!-- INDEX FINGER JOINTS -->
  <joint name="left_hand_Index_Finger_Distal" type="revolute">
    <parent link="left_hand_l" />
    <child link="left_hand_p" />
    <limit effort="1000.0" lower="0" upper="1.334" velocity="1" />
    <origin rpy="0 0 0" xyz="0.04804 0 0" />
    <axis xyz="0 0 1" />
  </joint>
  <joint name="left_hand_Index_Finger_Proximal" type="revolute">
    <parent link="left_hand_virtual_l" />
    <child link="left_hand_l" />
    <limit effort="1000.0" lower="0.0" upper="0.79849" velocity="1" />
    <origin rpy="-1.5707 0 0" xyz="0 0 0" />
    <axis xyz="0 0 1" />
  </joint>
  <!-- JOINT Finger_Spread in BASE_LINE section for better UX -->
  <joint name="left_hand_j14" type="revolute">
    <parent link="left_hand_p" />
    <child link="left_hand_t" />
    <limit effort="1000.0" lower="0" upper="1.394" velocity="1" />
    <origin rpy="0 0 0" xyz="0.026 0 0" />
    <axis xyz="0 0 1" />
    <mimic joint="left_hand_Index_Finger_Distal" multiplier="1.0450" offset="0" />
  </joint>
  <!-- MIDDLE FINGER JOINTS -->
  <joint name="left_hand_Middle_Finger_Proximal" type="revolute">
    <parent link="left_hand_virtual_k" />
    <child link="left_hand_k" />
    <limit effort="1000.0" lower="0.0" upper="0.79849" velocity="1" />
    <origin rpy="-1.5707 0 0" xyz="0 0 0" />
    <axis xyz="0 0 1" />
  </joint>
  <joint name="left_hand_Middle_Finger_Distal" type="revolute">
    <parent link="left_hand_k" />
    <child link="left_hand_o" />
    <limit effort="1000.0" lower="0" upper="1.334" velocity="1" />
    <origin rpy="0 0 0" xyz="0.05004 0 0" />
    <axis xyz="0 0 1" />
  </joint>
  <joint name="left_hand_j15" type="revolute">
    <parent link="left_hand_o" />
    <child link="left_hand_s" />
    <limit effort="1000.0" lower="0" upper="1.334" velocity="1" />
    <origin rpy="0 0 0" xyz="0.032 0 0" />
    <axis xyz="0 0 1" />
    <mimic joint="left_hand_Middle_Finger_Distal" multiplier="1.0454" offset="0" />
  </joint>
  <!-- RING FINGER JOINTS -->
  <joint name="left_hand_Ring_Finger" type="revolute">
    <parent link="left_hand_virtual_j" />
    <child link="left_hand_j" />
    <limit effort="1000.0" lower="0.0" upper="0.98175" velocity="1" />
    <origin rpy="1.5707 0 0" xyz="0 0 0" />
    <axis xyz="0 0 1" />
  </joint>
  <joint name="left_hand_j12" type="revolute">
    <parent link="left_hand_j" />
    <child link="left_hand_n" />
    <limit effort="1000.0" lower="0" upper="1.334" velocity="1" />
    <origin rpy="0 0 0" xyz="0.05004 0 0" />
    <axis xyz="0 0 1" />
    <mimic joint="left_hand_Ring_Finger" multiplier="1.3588" offset="0" />
  </joint>
  <joint name="left_hand_j16" type="revolute">
    <parent link="left_hand_n" />
    <child link="left_hand_r" />
    <limit effort="1000.0" lower="0" upper="1.395" velocity="1" />
    <origin rpy="0 0 0" xyz="0.032 0 0" />
    <axis xyz="0 0 1" />
    <mimic joint="left_hand_Ring_Finger" multiplier="1.42093" offset="0" />
  </joint>
  <!-- PINKY JOINTS -->
  <joint name="left_hand_Pinky" type="revolute">
    <parent link="left_hand_virtual_i" />
    <child link="left_hand_i" />
    <limit effort="1000.0" lower="0.0" upper="0.98175" velocity="1" />
    <origin rpy="1.5707 0 0" xyz="0 0 0" />
    <axis xyz="0 0 1" />
  </joint>
  <joint name="left_hand_j13" type="revolute">
    <parent link="left_hand_i" />
    <child link="left_hand_m" />
    <limit effort="1000.0" lower="0" upper="1.334" velocity="1" />
    <origin rpy="0 0 0" xyz="0.04454 0 0" />
    <axis xyz="0 0 1" />
    <mimic joint="left_hand_Pinky" multiplier="1.35880" offset="0" />
  </joint>
  <joint name="left_hand_j17" type="revolute">
    <parent link="left_hand_m" />
    <child link="left_hand_q" />
    <limit effort="1000.0" lower="0" upper="1.3971" velocity="1" />
    <origin rpy="0 0 0" xyz="0.022 0 0" />
    <axis xyz="0 0 1" />
    <mimic joint="left_hand_Pinky" multiplier="1.42307" offset="0" />
  </joint>
  <joint name="left_hand_index_spread" type="revolute">
    <parent link="left_hand_d2" />
    <child link="left_hand_virtual_l" />
    <limit effort="1000.0" lower="0.0" upper="0.28833" velocity="1" />
    <origin rpy="0 -1.5707 1.5707" xyz="0.025 0 0.110" />
    <axis xyz="0 0 -1" />
    <mimic joint="left_hand_Finger_Spread" multiplier="0.5" offset="0" />
  </joint>
  <joint name="left_hand_middle_spread_dummy" type="fixed">
    <parent link="left_hand_d" />
    <child link="left_hand_virtual_k" />
    <origin rpy="0 -1.5707 1.5707" xyz="0 0 0.110" />
  </joint>
  <joint name="left_hand_ring_spread" type="revolute">
    <parent link="left_hand_e5" />
    <child link="left_hand_virtual_j" />
    <limit effort="1000.0" lower="0.0" upper="0.28833" velocity="1" />
    <origin rpy="-1.5707 -1.5707 0" xyz="-0.003855 0 0.0655" />
    <axis xyz="0 0 -1" />
    <mimic joint="left_hand_Finger_Spread" multiplier="0.5" offset="0" />
  </joint>
  <joint name="left_hand_Finger_Spread" type="revolute">
    <parent link="left_hand_e4" />
    <child link="left_hand_virtual_i" />
    <limit effort="1000.0" lower="0.0" upper="0.5829" velocity="1" />
    <origin rpy="-1.5707 -1.5707 0" xyz="-0.025355 0 0.056" />
    <axis xyz="0 0 -1" />
  </joint>
  <transmission name="left_hand_Thumb_Opposition_trans">
    <type>transmission_interface/SimpleTransmission</type>
    <joint name="left_hand_Thumb_Opposition">
      <!-- <hardwareInterface>hardware_interface/EffortJointInterface</hardwareInterface> -->
      <hardwareInterface>hardware_interface/PositionJointInterface</hardwareInterface>
      <!-- <hardwareInterface>hardware_interface/VelocityJointInterface</hardwareInterface> -->
    </joint>
    <actuator name="left_hand_Thumb_Opposition_motor">
      <mechanicalReduction>1</mechanicalReduction>
      <!-- <hardwareInterface>hardware_interface/EffortJointInterface</hardwareInterface> -->
      <hardwareInterface>hardware_interface/PositionJointInterface</hardwareInterface>
      <!-- <hardwareInterface>hardware_interface/VelocityJointInterface</hardwareInterface> -->
    </actuator>
  </transmission>
  <transmission name="left_hand_Thumb_Flexion_trans">
    <type>transmission_interface/SimpleTransmission</type>
    <joint name="left_hand_Thumb_Flexion">
      <!-- <hardwareInterface>hardware_interface/EffortJointInterface</hardwareInterface> -->
      <hardwareInterface>hardware_interface/PositionJointInterface</hardwareInterface>
      <!-- <hardwareInterface>hardware_interface/VelocityJointInterface</hardwareInterface> -->
    </joint>
    <actuator name="left_hand_Thumb_Flexion_motor">
      <mechanicalReduction>1</mechanicalReduction>
      <!-- <hardwareInterface>hardware_interface/EffortJointInterface</hardwareInterface> -->
      <hardwareInterface>hardware_interface/PositionJointInterface</hardwareInterface>
      <!-- <hardwareInterface>hardware_interface/VelocityJointInterface</hardwareInterface> -->
    </actuator>
  </transmission>
  <transmission name="left_hand_Index_Finger_Proximal_trans">
    <type>transmission_interface/SimpleTransmission</type>
    <joint name="left_hand_Index_Finger_Proximal">
      <!-- <hardwareInterface>hardware_interface/EffortJointInterface</hardwareInterface> -->
      <hardwareInterface>hardware_interface/PositionJointInterface</hardwareInterface>
      <!-- <hardwareInterface>hardware_interface/VelocityJointInterface</hardwareInterface> -->
    </joint>
    <actuator name="left_hand_Index_Finger_Proximal_motor">
      <mechanicalReduction>1</mechanicalReduction>
      <!-- <hardwareInterface>hardware_interface/EffortJointInterface</hardwareInterface> -->
      <hardwareInterface>hardware_interface/PositionJointInterface</hardwareInterface>
      <!-- <hardwareInterface>hardware_interface/VelocityJointInterface</hardwareInterface> -->
    </actuator>
  </transmission>
  <transmission name="left_hand_Index_Finger_Distal_trans">
    <type>transmission_interface/SimpleTransmission</type>
    <joint name="left_hand_Index_Finger_Distal">
      <!-- <hardwareInterface>hardware_interface/EffortJointInterface</hardwareInterface> -->
      <hardwareInterface>hardware_interface/PositionJointInterface</hardwareInterface>
      <!-- <hardwareInterface>hardware_interface/VelocityJointInterface</hardwareInterface> -->
    </joint>
    <actuator name="left_hand_Index_Finger_Distal_motor">
      <mechanicalReduction>1</mechanicalReduction>
      <!-- <hardwareInterface>hardware_interface/EffortJointInterface</hardwareInterface> -->
      <hardwareInterface>hardware_interface/PositionJointInterface</hardwareInterface>
      <!-- <hardwareInterface>hardware_interface/VelocityJointInterface</hardwareInterface> -->
    </actuator>
  </transmission>
  <transmission name="left_hand_Middle_Finger_Proximal_trans">
    <type>transmission_interface/SimpleTransmission</type>
    <joint name="left_hand_Middle_Finger_Proximal">
      <!-- <hardwareInterface>hardware_interface/EffortJointInterface</hardwareInterface> -->
      <hardwareInterface>hardware_interface/PositionJointInterface</hardwareInterface>
      <!-- <hardwareInterface>hardware_interface/VelocityJointInterface</hardwareInterface> -->
    </joint>
    <actuator name="left_hand_Middle_Finger_Proximal_motor">
      <mechanicalReduction>1</mechanicalReduction>
      <!-- <hardwareInterface>hardware_interface/EffortJointInterface</hardwareInterface> -->
      <hardwareInterface>hardware_interface/PositionJointInterface</hardwareInterface>
      <!-- <hardwareInterface>hardware_interface/VelocityJointInterface</hardwareInterface> -->
    </actuator>
  </transmission>
  <transmission name="left_hand_Middle_Finger_Distal_trans">
    <type>transmission_interface/SimpleTransmission</type>
    <joint name="left_hand_Middle_Finger_Distal">
      <!-- <hardwareInterface>hardware_interface/EffortJointInterface</hardwareInterface> -->
      <hardwareInterface>hardware_interface/PositionJointInterface</hardwareInterface>
      <!-- <hardwareInterface>hardware_interface/VelocityJointInterface</hardwareInterface> -->
    </joint>
    <actuator name="left_hand_Middle_Finger_Distal_motor">
      <mechanicalReduction>1</mechanicalReduction>
      <!-- <hardwareInterface>hardware_interface/EffortJointInterface</hardwareInterface> -->
      <hardwareInterface>hardware_interface/PositionJointInterface</hardwareInterface>
      <!-- <hardwareInterface>hardware_interface/VelocityJointInterface</hardwareInterface> -->
    </actuator>
  </transmission>
  <transmission name="left_hand_Finger_Spread_trans">
    <type>transmission_interface/SimpleTransmission</type>
    <joint name="left_hand_Finger_Spread">
      <!-- <hardwareInterface>hardware_interface/EffortJointInterface</hardwareInterface> -->
      <hardwareInterface>hardware_interface/PositionJointInterface</hardwareInterface>
      <!-- <hardwareInterface>hardware_interface/VelocityJointInterface</hardwareInterface> -->
    </joint>
    <actuator name="left_hand_Finger_Spread_motor">
      <mechanicalReduction>1</mechanicalReduction>
      <!-- <hardwareInterface>hardware_interface/EffortJointInterface</hardwareInterface> -->
      <hardwareInterface>hardware_interface/PositionJointInterface</hardwareInterface>
      <!-- <hardwareInterface>hardware_interface/VelocityJointInterface</hardwareInterface> -->
    </actuator>
  </transmission>
  <transmission name="left_hand_Pinky_trans">
    <type>transmission_interface/SimpleTransmission</type>
    <joint name="left_hand_Pinky">
      <!-- <hardwareInterface>hardware_interface/EffortJointInterface</hardwareInterface> -->
      <hardwareInterface>hardware_interface/PositionJointInterface</hardwareInterface>
      <!-- <hardwareInterface>hardware_interface/VelocityJointInterface</hardwareInterface> -->
    </joint>
    <actuator name="left_hand_Pinky_motor">
      <mechanicalReduction>1</mechanicalReduction>
      <!-- <hardwareInterface>hardware_interface/EffortJointInterface</hardwareInterface> -->
      <hardwareInterface>hardware_interface/PositionJointInterface</hardwareInterface>
      <!-- <hardwareInterface>hardware_interface/VelocityJointInterface</hardwareInterface> -->
    </actuator>
  </transmission>
  <transmission name="left_hand_Ring_Finger_trans">
    <type>transmission_interface/SimpleTransmission</type>
    <joint name="left_hand_Ring_Finger">
      <!-- <hardwareInterface>hardware_interface/EffortJointInterface</hardwareInterface> -->
      <hardwareInterface>hardware_interface/PositionJointInterface</hardwareInterface>
      <!-- <hardwareInterface>hardware_interface/VelocityJointInterface</hardwareInterface> -->
    </joint>
    <actuator name="left_hand_Ring_Finger_motor">
      <mechanicalReduction>1</mechanicalReduction>
      <!-- <hardwareInterface>hardware_interface/EffortJointInterface</hardwareInterface> -->
      <hardwareInterface>hardware_interface/PositionJointInterface</hardwareInterface>
      <!-- <hardwareInterface>hardware_interface/VelocityJointInterface</hardwareInterface> -->
    </actuator>
  </transmission>
  <gazebo>
    <plugin filename="libroboticsgroup_upatras_gazebo_mimic_joint_plugin.so"
      name="left_hand_j3_mimic_joint_plugin">
      <joint>left_hand_Thumb_Flexion</joint>
      <mimicJoint>left_hand_j3</mimicJoint>
      <!-- if set to true, PID parameters from "/gazebo_ros_control/pid_gains/${mimic_joint}" are
      loaded -->
      <hasPID />
      <multiplier>1.01511</multiplier>
      <offset>0</offset>
      <sensitiveness>0.0</sensitiveness>
      <!-- if absolute difference between setpoint and process value is below this threshold, do
      nothing; 0.0 = disable [rad] -->
      <maxEffort>100.0</maxEffort>
      <robotNamespace>/</robotNamespace>
    </plugin>
  </gazebo>
  <gazebo>
    <plugin filename="libroboticsgroup_upatras_gazebo_mimic_joint_plugin.so"
      name="left_hand_j4_mimic_joint_plugin">
      <joint>left_hand_Thumb_Flexion</joint>
      <mimicJoint>left_hand_j4</mimicJoint>
      <!-- if set to true, PID parameters from "/gazebo_ros_control/pid_gains/${mimic_joint}" are
      loaded -->
      <hasPID />
      <multiplier>1.44889</multiplier>
      <offset>0</offset>
      <sensitiveness>0.0</sensitiveness>
      <!-- if absolute difference between setpoint and process value is below this threshold, do
      nothing; 0.0 = disable [rad] -->
      <maxEffort>100.0</maxEffort>
      <robotNamespace>/</robotNamespace>
    </plugin>
  </gazebo>
  <gazebo>
    <plugin filename="libroboticsgroup_upatras_gazebo_mimic_joint_plugin.so"
      name="left_hand_j14_mimic_joint_plugin">
      <joint>left_hand_Index_Finger_Distal</joint>
      <mimicJoint>left_hand_j14</mimicJoint>
      <!-- if set to true, PID parameters from "/gazebo_ros_control/pid_gains/${mimic_joint}" are
      loaded -->
      <hasPID />
      <multiplier>1.045</multiplier>
      <offset>0</offset>
      <sensitiveness>0.0</sensitiveness>
      <!-- if absolute difference between setpoint and process value is below this threshold, do
      nothing; 0.0 = disable [rad] -->
      <maxEffort>100.0</maxEffort>
      <robotNamespace>/</robotNamespace>
    </plugin>
  </gazebo>
  <gazebo>
    <plugin filename="libroboticsgroup_upatras_gazebo_mimic_joint_plugin.so"
      name="left_hand_j15_mimic_joint_plugin">
      <joint>left_hand_Middle_Finger_Distal</joint>
      <mimicJoint>left_hand_j15</mimicJoint>
      <!-- if set to true, PID parameters from "/gazebo_ros_control/pid_gains/${mimic_joint}" are
      loaded -->
      <hasPID />
      <multiplier>1.0454</multiplier>
      <offset>0</offset>
      <sensitiveness>0.0</sensitiveness>
      <!-- if absolute difference between setpoint and process value is below this threshold, do
      nothing; 0.0 = disable [rad] -->
      <maxEffort>100.0</maxEffort>
      <robotNamespace>/</robotNamespace>
    </plugin>
  </gazebo>
  <gazebo>
    <plugin filename="libroboticsgroup_upatras_gazebo_mimic_joint_plugin.so"
      name="left_hand_j12_mimic_joint_plugin">
      <joint>left_hand_Ring_Finger</joint>
      <mimicJoint>left_hand_j12</mimicJoint>
      <!-- if set to true, PID parameters from "/gazebo_ros_control/pid_gains/${mimic_joint}" are
      loaded -->
      <hasPID />
      <multiplier>1.3588</multiplier>
      <offset>0</offset>
      <sensitiveness>0.0</sensitiveness>
      <!-- if absolute difference between setpoint and process value is below this threshold, do
      nothing; 0.0 = disable [rad] -->
      <maxEffort>100.0</maxEffort>
      <robotNamespace>/</robotNamespace>
    </plugin>
  </gazebo>
  <gazebo>
    <plugin filename="libroboticsgroup_upatras_gazebo_mimic_joint_plugin.so"
      name="left_hand_j16_mimic_joint_plugin">
      <joint>left_hand_Ring_Finger</joint>
      <mimicJoint>left_hand_j16</mimicJoint>
      <!-- if set to true, PID parameters from "/gazebo_ros_control/pid_gains/${mimic_joint}" are
      loaded -->
      <hasPID />
      <multiplier>1.42093</multiplier>
      <offset>0</offset>
      <sensitiveness>0.0</sensitiveness>
      <!-- if absolute difference between setpoint and process value is below this threshold, do
      nothing; 0.0 = disable [rad] -->
      <maxEffort>100.0</maxEffort>
      <robotNamespace>/</robotNamespace>
    </plugin>
  </gazebo>
  <gazebo>
    <plugin filename="libroboticsgroup_upatras_gazebo_mimic_joint_plugin.so"
      name="left_hand_j13_mimic_joint_plugin">
      <joint>left_hand_Pinky</joint>
      <mimicJoint>left_hand_j13</mimicJoint>
      <!-- if set to true, PID parameters from "/gazebo_ros_control/pid_gains/${mimic_joint}" are
      loaded -->
      <hasPID />
      <multiplier>1.3588</multiplier>
      <offset>0</offset>
      <sensitiveness>0.0</sensitiveness>
      <!-- if absolute difference between setpoint and process value is below this threshold, do
      nothing; 0.0 = disable [rad] -->
      <maxEffort>100.0</maxEffort>
      <robotNamespace>/</robotNamespace>
    </plugin>
  </gazebo>
  <gazebo>
    <plugin filename="libroboticsgroup_upatras_gazebo_mimic_joint_plugin.so"
      name="left_hand_j17_mimic_joint_plugin">
      <joint>left_hand_Pinky</joint>
      <mimicJoint>left_hand_j17</mimicJoint>
      <!-- if set to true, PID parameters from "/gazebo_ros_control/pid_gains/${mimic_joint}" are
      loaded -->
      <hasPID />
      <multiplier>1.42307</multiplier>
      <offset>0</offset>
      <sensitiveness>0.0</sensitiveness>
      <!-- if absolute difference between setpoint and process value is below this threshold, do
      nothing; 0.0 = disable [rad] -->
      <maxEffort>100.0</maxEffort>
      <robotNamespace>/</robotNamespace>
    </plugin>
  </gazebo>
  <gazebo>
    <plugin filename="libroboticsgroup_upatras_gazebo_mimic_joint_plugin.so"
      name="left_hand_index_spread_mimic_joint_plugin">
      <joint>left_hand_Finger_Spread</joint>
      <mimicJoint>left_hand_index_spread</mimicJoint>
      <!-- if set to true, PID parameters from "/gazebo_ros_control/pid_gains/${mimic_joint}" are
      loaded -->
      <hasPID />
      <multiplier>0.5</multiplier>
      <offset>0</offset>
      <sensitiveness>0.0</sensitiveness>
      <!-- if absolute difference between setpoint and process value is below this threshold, do
      nothing; 0.0 = disable [rad] -->
      <maxEffort>100.0</maxEffort>
      <robotNamespace>/</robotNamespace>
    </plugin>
  </gazebo>
  <gazebo>
    <plugin filename="libroboticsgroup_upatras_gazebo_mimic_joint_plugin.so"
      name="left_hand_ring_spread_mimic_joint_plugin">
      <joint>left_hand_Finger_Spread</joint>
      <mimicJoint>left_hand_ring_spread</mimicJoint>
      <!-- if set to true, PID parameters from "/gazebo_ros_control/pid_gains/${mimic_joint}" are
      loaded -->
      <hasPID />
      <multiplier>0.5</multiplier>
      <offset>0</offset>
      <sensitiveness>0.0</sensitiveness>
      <!-- if absolute difference between setpoint and process value is below this threshold, do
      nothing; 0.0 = disable [rad] -->
      <maxEffort>100.0</maxEffort>
      <robotNamespace>/</robotNamespace>
    </plugin>
  </gazebo>

  <!-- ################################### -->
  <!-- ### End Schunk left hand       #### -->
  <!-- ################################### -->

  <gazebo>
    <plugin filename="libgazebo_ros_control.so" name="gazebo_ros_control">
      <legacyModeNS>false</legacyModeNS>
      <robotNamespace>/</robotNamespace>
      <robotSimType>gazebo_ros_control/DefaultRobotHWSim</robotSimType>
    </plugin>
  </gazebo>

</robot>
